Workbook

Sheet 24hr stool collections Mouse ID
A1: 1st 24hr stool collection (8/31/2018)
A2: Mouse ID | B2: ApoE-/- TRF | C2: ApoE-/- ad lib | D2: Ldlr-/- TRF | E2: Ldlr-/- ad lib
A3: 1 | B3: 123N | C3: 125N | D3: 130N | E3: 132N
A4: 2 | B4: 123L | C4: 125L | D4: 130L | E4: 132L
A5: 3 | B5: 123R | C5: 125R | D5: 130R | E5: 132R
A6: 4 | B6: 123B | C6: 125B | D6: 131N | E6: 133N
A7: 5 | B7: 124N | C7: 126N | D7: 131L | E7: 133L
A8: 6 | B8: 124L | C8: 126L | D8: 131R | E8: 133R
A13: 2nd 24hr stool collection (1/4/2019)
A14: Mouse ID | B14: ApoE-/- TRF | C14: ApoE-/- ad lib | D14: Ldlr-/- TRF | E14: Ldlr-/- ad lib
A15: 1 | B15: 123N | C15: dead | D15: 130N | E15: dead
A16: 2 | B16: 123L | C16: 125L | D16: dead | E16: 132L
A17: 3 | B17: 123R | C17: 125R | D17: 130R | E17: dead
A18: 4 | B18: dead | C18: 125B | D18: 131N | E18: 133N
A19: 5 | B19: 124N | C19: 126N | D19: 131L | E19: 133L
A20: 6 | B20: 124L | C20: 126L | D20: dead | E20: 133R

Sheet Mouse ID Key
D1: "Mouse Weights" Key | J1: "Food Consumed" Key
A2: Treatment Groups | D2: Mouse ID | E2: AT | F2: AA | G2: LT | H2: LA | J2: Mouse Cage | K2: AT | L2: AA | M2: LT | N2: LA
A3: Code | B3: Mouse & Condition | D3: 1 | E3: 123N | F3: 125N | G3: 130N | H3: 132N | J3: 1 | K3: 123 | L3: 125A | M3: 130 | N3: 132
A4: AT | B4: Apoe TRF | D4: 2 | E4: 123L | F4: 125L | G4: 130L | H4: 132L | J4: 2 | K4: 124 | L4: 126 | M4: 131 | N4: 133
A5: AA | B5: Apoe Ad LIB | D5: 3 | E5: 123R | F5: 125R | G5: 130R | H5: 132R | J5: 3 | L5: 125B
A6: LT | B6: Ldlr TRF | D6: 4 | E6: 123B | F6: 125B | G6: 131N | H6: 133N
A7: LA | B7: Ldlr Apoe | D7: 5 | E7: 124N | F7: 126N | G7: 131L | H7: 133L | J7: 8/13/2018-10/31/2018
D8: 6 | E8: 124L | F8: 126L | G8: 131R | H8: 133R | K8: AT | L8: AA | M8: LT | N8: LA
J9: 1 | K9: 4 | L9: 4 | M9: 3 | N9: 3
J10: 2 | K10: 2 | L10: 2 | M10: 3 | N10: 3
J12: 10/31/2018-11/07/2018
K13: AT | L13: AA | M13: LT | N13: LA
J14: 1 | K14: 4 | L14: 3 | M14: 3 | N14: 3
J15: 2 | K15: 2 | L15: 2 | M15: 3 | N15: 3
L16: 1
J18: 10/31/2018-11/07/2018
K19: AT | L19: AA | M19: LT | N19: LA
J20: 1 | K20: 4 | L20: 2 | M20: 3 | N20: 3
J21: 2 | K21: 2 | L21: 2 | M21: 2 | N21: 3
L22: 2
J24: 11/07/2018-12/19/2018
K25: AT | L25: AA | M25: LT | N25: LA
J26: 1 | K26: 3 | L26: 3 | M26: 3 | N26: 3
J27: 2 | K27: 2 | L27: 2 | M27: 2 | N27: 3
L28: 1

Sheet Mouse Weights
A1: Week 0 | B1: AT | C1: AA | D1: LT | E1: LA | F1: LABEL | G1: 4 days | H1: Week 0.5 | I1: AT | J1: AA | K1: LT | L1: LA | M1: LABEL | N1: 3 days | O1: Week 1 | P1: AT | Q1: AA | R1: LT | S1: LA | T1: LABEL | U1: 7 days | V1: Week 2 | W1: AT | X1: AA | Y1: LT | Z1: LA | AA1: LABEL | AB1: 9 days | AC1: Week 3 | AD1: AT | AE1: AA | AF1: LT | AG1: LA | AH1: LABEL | AI1: 7 days | AJ1: Week 4 | AK1: AT | AL1: AA | AM1: LT | AN1: LA | AO1: LABEL | AP1: 7 days | AQ1: Week 5 | AR1: AT | AS1: AA | AT1: LT | AU1: LA | AV1: LABEL | AW1: 7 days | AX1: Week 6 | AY1: AT | AZ1: AA | BA1: LT | BB1: LA | BC1: LABEL | BD1: 7 days | BE1: Week 7 | BF1: AT | BG1: AA | BH1: LT | BI1: LA | BJ1: LABEL | BK1: 9 days | BL1: Week 8 | BM1: AT | BN1: AA | BO1: LT | BP1: LA | BQ1: LABEL | BR1: 5 days | BS1: Week 9 | BT1: AT | BU1: AA | BV1: LT | BW1: LA | BX1: LABEL | BY1: 8 days | BZ1: Week 10 | CA1: AT | CB1: AA | CC1: LT | CD1: LA | CE1: LABEL | CF1: 6 days | CG1: Week 11 | CH1: AT | CI1: AA | CJ1: LT | CK1: LA | CL1: LABEL | CM1: 7 days | CN1: Week 12 | CO1: AT | CP1: AA | CQ1: LT | CR1: LA | CS1: LABEL | CT1: 7 days | CU1: Week 13 | CV1: AT | CW1: AA | CX1: LT | CY1: LA | CZ1: LABEL | DA1: 7 days | DB1: Week 14 | DC1: AT | DD1: AA | DE1: LT | DF1: LA | DG1: LABEL | DH1: 7 days | DI1: Week 15 | DJ1: AT | DK1: AA | DL1: LT | DM1: LA | DN1: LABEL | DO1: 7 days | DP1: Week 16 | DQ1: AT | DR1: AA | DS1: LT | DT1: LA | DU1: LABEL | DV1: 7 days | DW1: Week 17 | DX1: AT | DY1: AA | DZ1: LT | EA1: LA | EB1: LABEL | EC1: 7 days | ED1: Week 18 | EE1: AT | EF1: AA | EG1: LT | EH1: LA | EI1: LABEL | EJ1: 9 days | EK1: Week 19 | EL1: AT | EM1: AA | EN1: LT | EO1: LA | EP1: LABEL | EQ1: 6 days | ER1: Week 20 | ES1: AT | ET1: AA | EU1: LT | EV1: LA | EW1: LABEL | EX1: 6 days | EY1: Week 21 | EZ1: AT | FA1: AA | FB1: LT | FC1: LA | FD1: LABEL | FE1: 8 days | FF1: Week 22 | FG1: AT | FH1: AA | FI1: LT | FJ1: LA | FK1: LABEL | FL1: 5 days | FM1: Week 23 | FN1: AT | FO1: AA | FP1: LT | FQ1: LA | FR1: LABEL
A2: 1 | B2: 26.7 | C2: 24.4 | D2: 24.5 | E2: 24 | F2: 0 | H2: 1 | I2: no weights | J2: no weights | K2: no weights | L2: no weights | M2: 0.5 | O2: 1 | P2: 23.7 | Q2: 23.1 | R2: 22.7 | S2: 23 | T2: 1 | V2: 1 | W2: 23.8 | X2: 22.2 | Y2: 23.7 | Z2: 23.2 | AA2: 2 | AC2: 1 | AD2: 26.7 | AE2: 23.6 | AF2: 23 | AG2: 24 | AH2: 3 | AJ2: 1 | AK2: 26.9 | AL2: 24.6 | AM2: 25.2 | AN2: 23.9 | AO2: 4 | AQ2: 1 | AR2: 27.9 | AS2: 24.5 | AT2: 26 | AU2: 24.6 | AV2: 5 | AX2: 1 | AY2: 27.5 | AZ2: 25.2 | BA2: 26.7 | BB2: 25 | BC2: 6 | BE2: 1 | BF2: 28.1 | BG2: 24.1 | BH2: 27.2 | BI2: 25.4 | BJ2: 7 | BL2: 1 | BM2: 28.9 | BN2: 25.5 | BO2: 28.2 | BP2: 28 | BQ2: 8 | BS2: 1 | BT2: 29.6 | BU2: 27.2 | BV2: 28.2 | BW2: 25.6 | BX2: 9 | BZ2: 1 | CA2: 31.2 | CB2: 25.5 | CC2: 28.6 | CD2: 26.3 | CE2: 10 | CG2: 1 | CH2: 30.4 | CI2: 25.3 | CJ2: 29.8 | CK2: 27.7 | CL2: 11 | CN2: 1 | CO2: 32.7 | CP2: 26 | CQ2: 28.9 | CR2: 25.5 | CS2: 12 | CU2: 1 | CV2: 32.3 | CW2: 27.3 | CX2: 29.9 | CY2: 25.2 | CZ2: 13 | DB2: 1 | DC2: 34.6 | DD2: 26.9 | DE2: 29.3 | DF2: 26.5 | DG2: 14 | DI2: 1 | DJ2: 34.6 | DK2: 27.9 | DL2: 30.5 | DM2: 26.9 | DN2: 15 | DP2: 1 | DQ2: 36.3 | DR2: 26 | DS2: 30.6 | DT2: 26.5 | DU2: 16 | DW2: 1 | DX2: 36.1 | DY2: 30.8 | DZ2: 29.8 | EA2: 26.3 | EB2: 17 | ED2: 1 | EE2: 37.6 | EF2: DEAD | EG2: 31.1 | EH2: 23.6 | EI2: 18 | EK2: 1 | EL2: no weights | EM2: DEAD | EN2: no weights | EO2: no weights | EP2: 19 | ER2: 1 | ES2: 38.2 | ET2: DEAD | EU2: 31.9 | EV2: DEAD | EW2: 20 | EY2: 1 | EZ2: 38.2 | FA2: DEAD | FB2: 32.7 | FC2: DEAD | FD2: 21 | FF2: 1 | FG2: metabolic cage | FH2: DEAD | FI2: metabolic cage | FJ2: DEAD | FK2: 22 | FM2: 1 | FN2: 36.4 | FO2: DEAD | FP2: 32.4 | FQ2: DEAD | FR2: 23
A3: 2 | B3: 24.6 | C3: 24.9 | D3: 25.6 | E3: 25.5 | F3: 0 | H3: 2 | I3: no weights | J3: no weights | K3: no weights | L3: no weights | M3: 0.5 | O3: 2 | P3: 22.9 | Q3: 22.3 | R3: 24.3 | S3: 25.2 | T3: 1 | V3: 2 | W3: 23.5 | X3: 24 | Y3: 25 | Z3: 25.9 | AA3: 2 | AC3: 2 | AD3: 24 | AE3: 23 | AF3: 25.5 | AG3: 26.9 | AH3: 3 | AJ3: 2 | AK3: 25.7 | AL3: 25.6 | AM3: 26.9 | AN3: 26.8 | AO3: 4 | AQ3: 2 | AR3: 26.6 | AS3: 25.7 | AT3: 28 | AU3: 27.1 | AV3: 5 | AX3: 2 | AY3: 26.5 | AZ3: 26.7 | BA3: 28.5 | BB3: 26.5 | BC3: 6 | BE3: 2 | BF3: 27 | BG3: 25.9 | BH3: 28.9 | BI3: 27.5 | BJ3: 7 | BL3: 2 | BM3: 27.9 | BN3: 26.5 | BO3: 29.5 | BP3: 28.1 | BQ3: 8 | BS3: 2 | BT3: 28.1 | BU3: 29.2 | BV3: 29.4 | BW3: 27.6 | BX3: 9 | BZ3: 2 | CA3: 28.7 | CB3: 27.6 | CC3: 29.7 | CD3: 27.2 | CE3: 10 | CG3: 2 | CH3: 28.8 | CI3: 27.4 | CJ3: 30.2 | CK3: 28.2 | CL3: 11 | CN3: 2 | CO3: 30 | CP3: 28.4 | CQ3: 30.3 | CR3: 26.1 | CS3: 12 | CU3: 2 | CV3: 30.2 | CW3: 29.9 | CX3: 30.8 | CY3: 27 | CZ3: 13 | DB3: 2 | DC3: 30.8 | DD3: 25.5 | DE3: 30.8 | DF3: 27 | DG3: 14 | DI3: 2 | DJ3: 31.9 | DK3: 28.9 | DL3: 30.3 | DM3: 26.7 | DN3: 15 | DP3: 2 | DQ3: 32.6 | DR3: 27 | DS3: 31 | DT3: 26.9 | DU3: 16 | DW3: 2 | DX3: 33.6 | DY3: 26.2 | DZ3: 30.9 | EA3: 28.1 | EB3: 17 | ED3: 2 | EE3: 34.4 | EF3: 27.8 | EG3: DEAD | EH3: 24.7 | EI3: 18 | EK3: 2 | EL3: no weights | EM3: no weights | EN3: DEAD | EO3: no weights | EP3: 19 | ER3: 2 | ES3: 36 | ET3: 26 | EU3: DEAD | EV3: 28 | EW3: 20 | EY3: 2 | EZ3: 35.6 | FA3: 26.5 | FB3: DEAD | FC3: 28.4 | FD3: 21 | FF3: 2 | FG3: 28.8 | FH3: metabolic cage | FI3: DEAD | FJ3: metabolic cage | FK3: 22 | FM3: 2 | FN3: 26.3 | FO3: 26.2 | FP3: DEAD | FQ3: 27.8 | FR3: 23
A4: 3 | B4: 26.9 | C4: 24.3 | D4: 25.3 | E4: 23.3 | F4: 0 | H4: 3 | I4: no weights | J4: no weights | K4: no weights | L4: no weights | M4: 0.5 | O4: 3 | P4: 24.8 | Q4: 22.3 | R4: 23.5 | S4: 23.5 | T4: 1 | V4: 3 | W4: 25.4 | X4: 22 | Y4: 24.1 | Z4: 23.8 | AA4: 2 | AC4: 3 | AD4: 25 | AE4: 24.8 | AF4: 24.2 | AG4: 24.8 | AH4: 3 | AJ4: 3 | AK4: 27.5 | AL4: 23.3 | AM4: 26.3 | AN4: 24.6 | AO4: 4 | AQ4: 3 | AR4: 29.1 | AS4: 24.2 | AT4: 26.8 | AU4: 25.4 | AV4: 5 | AX4: 3 | AY4: 27.3 | AZ4: 24.1 | BA4: 27.2 | BB4: 25.7 | BC4: 6 | BE4: 3 | BF4: 28.3 | BG4: 26.9 | BH4: 27.6 | BI4: 26 | BJ4: 7 | BL4: 3 | BM4: 29.3 | BN4: 24.5 | BO4: 25.8 | BP4: 27.9 | BQ4: 8 | BS4: 3 | BT4: 29.9 | BU4: 25.5 | BV4: 28.7 | BW4: 27.1 | BX4: 9 | BZ4: 3 | CA4: 31.5 | CB4: 25.8 | CC4: 29.3 | CD4: 26.7 | CE4: 10 | CG4: 3 | CH4: 31.2 | CI4: 25.6 | CJ4: 29.8 | CK4: 28 | CL4: 11 | CN4: 3 | CO4: 31.8 | CP4: 25.7 | CQ4: 29.5 | CR4: 26.2 | CS4: 12 | CU4: 3 | CV4: 32.8 | CW4: 26.5 | CX4: 30.7 | CY4: 27.2 | CZ4: 13 | DB4: 3 | DC4: 33.8 | DD4: 24.7 | DE4: 30.5 | DF4: 27.1 | DG4: 14 | DI4: 3 | DJ4: 35 | DK4: 25.1 | DL4: 29.8 | DM4: 26.9 | DN4: 15 | DP4: 3 | DQ4: 35.6 | DR4: 29.2 | DS4: 29.8 | DT4: 26.2 | DU4: 16 | DW4: 3 | DX4: 36.6 | DY4: 26.5 | DZ4: 30.9 | EA4: 26.7 | EB4: 17 | ED4: 3 | EE4: 36.2 | EF4: 26.2 | EG4: 29.6 | EH4: DEAD | EI4: 18 | EK4: 3 | EL4: no weights | EM4: no weights | EN4: no weights | EO4: DEAD | EP4: 19 | ER4: 3 | ES4: 36.9 | ET4: 29.5 | EU4: 30 | EV4: DEAD | EW4: 20 | EY4: 3 | EZ4: 38.3 | FA4: 28.7 | FB4: 30.2 | FC4: DEAD | FD4: 21 | FF4: 3 | FG4: metabolic cage | FH4: DEAD | FI4: metabolic cage | FJ4: DEAD | FK4: 22 | FM4: 3 | FN4: 38.6 | FO4: DEAD | FP4: 28.7 | FQ4: DEAD | FR4: 23
A5: 4 | B5: 24.4 | C5: 24.4 | D5: 23.4 | E5: 23 | F5: 0 | H5: 4 | I5: no weights | J5: no weights | K5: no weights | L5: no weights | M5: 0.5 | O5: 4 | P5: 23 | Q5: 22.1 | R5: 22 | S5: 21.2 | T5: 1 | V5: 4 | W5: 24.3 | X5: 22.5 | Y5: 25.1 | Z5: 22.3 | AA5: 2 | AC5: 4 | AD5: 26.6 | AE5: 24 | AF5: 25 | AG5: 23 | AH5: 3 | AJ5: 4 | AK5: 26.6 | AL5: 23.6 | AM5: 26.3 | AN5: 22.6 | AO5: 4 | AQ5: 4 | AR5: 27.4 | AS5: 23.7 | AT5: 27 | AU5: 24.6 | AV5: 5 | AX5: 4 | AY5: 29 | AZ5: 23.9 | BA5: 27.8 | BB5: 26.5 | BC5: 6 | BE5: 4 | BF5: 29.5 | BG5: 24.2 | BH5: 28 | BI5: 25 | BJ5: 7 | BL5: 4 | BM5: 30.7 | BN5: 24.9 | BO5: 28.8 | BP5: 26.3 | BQ5: 8 | BS5: 4 | BT5: 31 | BU5: 24.3 | BV5: 28.5 | BW5: 26.1 | BX5: 9 | BZ5: 4 | CA5: 32.7 | CB5: 25.2 | CC5: 29.5 | CD5: 26.5 | CE5: 10 | CG5: 4 | CH5: 31.9 | CI5: 24.4 | CJ5: 29.7 | CK5: 27.1 | CL5: 11 | CN5: 4 | CO5: 32.9 | CP5: 26.4 | CQ5: 29.6 | CR5: 26.4 | CS5: 12 | CU5: 4 | CV5: 33.2 | CW5: 26.2 | CX5: 30.1 | CY5: 25.5 | CZ5: 13 | DB5: 4 | DC5: 34.1 | DD5: 27.8 | DE5: 29.8 | DF5: 27.4 | DG5: 14 | DI5: 4 | DJ5: 35.1 | DK5: 27.1 | DL5: 30.5 | DM5: 27.8 | DN5: 15 | DP5: 4 | DQ5: 34.5 | DR5: 27.3 | DS5: 29.7 | DT5: 27.3 | DU5: 16 | DW5: 4 | DX5: 36.7 | DY5: 26.8 | DZ5: 32.3 | EA5: 27.6 | EB5: 17 | ED5: 4 | EE5: DEAD | EF5: 26.5 | EG5: 30.8 | EH5: 25.8 | EI5: 18 | EK5: 4 | EL5: DEAD | EM5: no weights | EN5: no weights | EO5: no weights | EP5: 19 | ER5: 4 | ES5: DEAD | ET5: 27.6 | EU5: 31.1 | EV5: 25.9 | EW5: 20 | EY5: 4 | EZ5: DEAD | FA5: 28.7 | FB5: 31.5 | FC5: 25.9 | FD5: 21 | FF5: 4 | FG5: DEAD | FH5: metabolic cage | FI5: metabolic cage | FJ5: metabolic cage | FK5: 22 | FM5: 4 | FN5: DEAD | FO5: 29.6 | FP5: 30.8 | FQ5: 25.2 | FR5: 23
A6: 5 | B6: 25 | C6: 28.8 | D6: 24.8 | E6: 25.1 | F6: 0 | H6: 5 | I6: no weights | J6: no weights | K6: no weights | L6: no weights | M6: 0.5 | O6: 5 | P6: 22.3 | Q6: 26.9 | R6: 23.9 | S6: 25.1 | T6: 1 | V6: 5 | W6: 23.6 | X6: 27.2 | Y6: 20.6 | Z6: 22.5 | AA6: 2 | AC6: 5 | AD6: 23.2 | AE6: 28.8 | AF6: 25.3 | AG6: 26.7 | AH6: 3 | AJ6: 5 | AK6: 24.2 | AL6: 28.9 | AM6: 26.8 | AN6: 25.3 | AO6: 4 | AQ6: 5 | AR6: 25.6 | AS6: 28.8 | AT6: 27 | AU6: 27.2 | AV6: 5 | AX6: 5 | AY6: 25.5 | AZ6: 28.5 | BA6: 28.4 | BB6: 29 | BC6: 6 | BE6: 5 | BF6: 25.9 | BG6: 23.6 | BH6: 28.4 | BI6: 27.7 | BJ6: 7 | BL6: 5 | BM6: 26.2 | BN6: 29.3 | BO6: 29.5 | BP6: 28.2 | BQ6: 8 | BS6: 5 | BT6: 27.1 | BU6: 29.1 | BV6: 30.6 | BW6: 28.4 | BX6: 9 | BZ6: 5 | CA6: 26.8 | CB6: 29.4 | CC6: 31.2 | CD6: 28 | CE6: 10 | CG6: 5 | CH6: 27.5 | CI6: 29.5 | CJ6: 30.6 | CK6: 28.9 | CL6: 11 | CN6: 5 | CO6: 31 | CP6: 30.5 | CQ6: 30.9 | CR6: 27.6 | CS6: 12 | CU6: 5 | CV6: 28.1 | CW6: 30.4 | CX6: 31.7 | CY6: 26.2 | CZ6: 13 | DB6: 5 | DC6: 28.4 | DD6: 29.6 | DE6: 31.1 | DF6: 27.3 | DG6: 14 | DI6: 5 | DJ6: 28.9 | DK6: 30.1 | DL6: 32.1 | DM6: 26 | DN6: 15 | DP6: 5 | DQ6: 33.3 | DR6: 30.2 | DS6: 31.6 | DT6: 27.2 | DU6: 16 | DW6: 5 | DX6: 29.3 | DY6: 30.6 | DZ6: 32.4 | EA6: 26.4 | EB6: 17 | ED6: 5 | EE6: 34.6 | EF6: 30.1 | EG6: 30.9 | EH6: 26.7 | EI6: 18 | EK6: 5 | EL6: no weights | EM6: no weights | EN6: no weights | EO6: no weights | EP6: 19 | ER6: 5 | ES6: 34.9 | ET6: 30.9 | EU6: 30.9 | EV6: 26.6 | EW6: 20 | EY6: 5 | EZ6: 35 | FA6: 31.1 | FB6: 30.9 | FC6: 27.4 | FD6: 21 | FF6: 5 | FG6: metabolic cage | FH6: metabolic cage | FI6: metabolic cage | FJ6: metabolic cage | FK6: 22 | FM6: 5 | FN6: 32.7 | FO6: 33.4 | FP6: 31 | FQ6: 23.5 | FR6: 23
A7: 6 | B7: 24.2 | C7: 23.7 | D7: 20.6 | E7: 23 | F7: 0 | H7: 6 | I7: no weights | J7: no weights | K7: no weights | L7: no weights | M7: 0.5 | O7: 6 | P7: 21.6 | Q7: 21.5 | R7: 19.9 | S7: 21.9 | T7: 1 | V7: 6 | W7: 23.8 | X7: 22.1 | Y7: 24 | Z7: 24.6 | AA7: 2 | AC7: 6 | AD7: 24.2 | AE7: 26.8 | AF7: 21 | AG7: 22.6 | AH7: 3 | AJ7: 6 | AK7: 26 | AL7: 22.8 | AM7: 22.3 | AN7: 23.5 | AO7: 4 | AQ7: 6 | AR7: 27.2 | AS7: 23.2 | AT7: 22.9 | AU7: 23.9 | AV7: 5 | AX7: 6 | AY7: 27.3 | AZ7: 23 | BA7: 23.8 | BB7: 25.8 | BC7: 6 | BE7: 6 | BF7: 27.9 | BG7: 29.2 | BH7: 24.2 | BI7: 25.4 | BJ7: 7 | BL7: 6 | BM7: 28.8 | BN7: 23.1 | BO7: 25.8 | BP7: 24.8 | BQ7: 8 | BS7: 6 | BT7: 29.3 | BU7: 22.4 | BV7: 25.6 | BW7: 25.5 | BX7: 9 | BZ7: 6 | CA7: 29.9 | CB7: 22.9 | CC7: 26.1 | CD7: 25.5 | CE7: 10 | CG7: 6 | CH7: 30.2 | CI7: 23 | CJ7: 25.1 | CK7: 25.8 | CL7: 11 | CN7: 6 | CO7: 27.9 | CP7: 24.6 | CQ7: DEAD | CR7: 25.3 | CS7: 12 | CU7: 6 | CV7: 30.7 | CW7: 24.3 | CX7: DEAD | CY7: 27.3 | CZ7: 13 | DB7: 6 | DC7: 31.8 | DD7: 24.3 | DE7: DEAD | DF7: 26.6 | DG7: 14 | DI7: 6 | DJ7: 32.2 | DK7: 24.9 | DL7: DEAD | DM7: 26.1 | DN7: 15 | DP7: 6 | DQ7: 29.1 | DR7: 25 | DS7: DEAD | DT7: 25.8 | DU7: 16 | DW7: 6 | DX7: 34 | DY7: 26.1 | DZ7: DEAD | EA7: 27.4 | EB7: 17 | ED7: 6 | EE7: 28.5 | EF7: 25.7 | EG7: DEAD | EH7: 27.1 | EI7: 18 | EK7: 6 | EL7: no weights | EM7: no weights | EN7: DEAD | EO7: no weights | EP7: 19 | ER7: 6 | ES7: 27.8 | ET7: 26 | EU7: DEAD | EV7: 27.7 | EW7: 20 | EY7: 6 | EZ7: 28.1 | FA7: 26.3 | FB7: DEAD | FC7: 25.5 | FD7: 21 | FF7: 6 | FG7: metabolic cage | FH7: 29.2 | FI7: DEAD | FJ7: metabolic cage | FK7: 22 | FM7: 6 | FN7: 26.4 | FO7: 27.1 | FP7: DEAD | FQ7: DEAD | FR7: 23
A8: Average | B8: =AVERAGE(B2:B7) -> 25.3 | C8: =AVERAGE(C2:C7) -> 25.083333 | D8: =AVERAGE(D2:D7) -> 24.033333 | E8: =AVERAGE(E2:E7) -> 23.983333 | H8: Average | I8: =AVERAGE(I2:I7) -> #DIV/0! | J8: =AVERAGE(J2:J7) -> #DIV/0! | K8: =AVERAGE(K2:K7) -> #DIV/0! | L8: =AVERAGE(L2:L7) -> #DIV/0! | O8: Average | P8: =AVERAGE(P2:P7) -> 23.05 | Q8: =AVERAGE(Q2:Q7) -> 23.033333 | R8: =AVERAGE(R2:R7) -> 22.716667 | S8: =AVERAGE(S2:S7) -> 23.316667 | V8: Average | W8: =AVERAGE(W2:W7) -> 24.066667 | X8: =AVERAGE(X2:X7) -> 23.333333 | Y8: =AVERAGE(Y2:Y7) -> 23.75 | Z8: =AVERAGE(Z2:Z7) -> 23.716667 | AC8: Average | AD8: =AVERAGE(AD2:AD7) -> 24.95 | AE8: =AVERAGE(AE2:AE7) -> 25.166667 | AF8: =AVERAGE(AF2:AF7) -> 24 | AG8: =AVERAGE(AG2:AG7) -> 24.666667 | AJ8: Average | AK8: =AVERAGE(AK2:AK7) -> 26.15 | AL8: =AVERAGE(AL2:AL7) -> 24.8 | AM8: =AVERAGE(AM2:AM7) -> 25.633333 | AN8: =AVERAGE(AN2:AN7) -> 24.45 | AQ8: Average | AR8: =AVERAGE(AR2:AR7) -> 27.3 | AS8: =AVERAGE(AS2:AS7) -> 25.016667 | AT8: =AVERAGE(AT2:AT7) -> 26.283333 | AU8: =AVERAGE(AU2:AU7) -> 25.466667 | AX8: Average | AY8: =AVERAGE(AY2:AY7) -> 27.183333 | AZ8: =AVERAGE(AZ2:AZ7) -> 25.233333 | BA8: =AVERAGE(BA2:BA7) -> 27.066667 | BB8: =AVERAGE(BB2:BB7) -> 26.416667 | BE8: Average | BF8: =AVERAGE(BF2:BF7) -> 27.783333 | BG8: =AVERAGE(BG2:BG7) -> 25.65 | BH8: =AVERAGE(BH2:BH7) -> 27.383333 | BI8: =AVERAGE(BI2:BI7) -> 26.166667 | BL8: Average | BM8: =AVERAGE(BM2:BM7) -> 28.633333 | BN8: =AVERAGE(BN2:BN7) -> 25.633333 | BO8: =AVERAGE(BO2:BO7) -> 27.933333 | BP8: =AVERAGE(BP2:BP7) -> 27.216667 | BS8: Average | BT8: =AVERAGE(BT2:BT7) -> 29.166667 | BU8: =AVERAGE(BU2:BU7) -> 26.283333 | BV8: =AVERAGE(BV2:BV7) -> 28.5 | BW8: =AVERAGE(BW2:BW7) -> 26.716667 | BZ8: Average | CA8: =AVERAGE(CA2:CA7) -> 30.133333 | CB8: =AVERAGE(CB2:CB7) -> 26.066667 | CC8: =AVERAGE(CC2:CC7) -> 29.066667 | CD8: =AVERAGE(CD2:CD7) -> 26.7 | CG8: Average | CH8: =AVERAGE(CH2:CH7) -> 30 | CI8: =AVERAGE(CI2:CI7) -> 25.866667 | CJ8: =AVERAGE(CJ2:CJ7) -> 29.2 | CK8: =AVERAGE(CK2:CK7) -> 27.616667 | CN8: Average | CO8: =AVERAGE(CO2:CO7) -> 31.05 | CP8: =AVERAGE(CP2:CP7) -> 26.933333 | CQ8: =AVERAGE(CQ2:CQ6) -> 29.84 | CR8: =AVERAGE(CR2:CR7) -> 26.183333 | CU8: Average | CV8: =AVERAGE(CV2:CV7) -> 31.216667 | CW8: =AVERAGE(CW2:CW7) -> 27.433333 | CX8: =AVERAGE(CX2:CX6) -> 30.64 | CY8: =AVERAGE(CY2:CY7) -> 26.4 | DB8: Average | DC8: =AVERAGE(DC2:DC7) -> 32.25 | DD8: =AVERAGE(DD2:DD7) -> 26.466667 | DE8: =AVERAGE(DE2:DE6) -> 30.3 | DF8: =AVERAGE(DF2:DF7) -> 26.983333 | DI8: Average | DJ8: =AVERAGE(DJ2:DJ7) -> 32.95 | DK8: =AVERAGE(DK2:DK7) -> 27.333333 | DL8: =AVERAGE(DL2:DL6) -> 30.64 | DM8: =AVERAGE(DM2:DM7) -> 26.733333 | DP8: Average | DQ8: =AVERAGE(DQ2:DQ7) -> 33.566667 | DR8: =AVERAGE(DR2:DR7) -> 27.45 | DS8: =AVERAGE(DS2:DS6) -> 30.54 | DT8: =AVERAGE(DT2:DT7) -> 26.65 | DW8: Average | DX8: =AVERAGE(DX2:DX7) -> 34.383333 | DY8: =AVERAGE(DY2:DY7) -> 27.833333 | DZ8: =AVERAGE(DZ2:DZ6) -> 31.26 | EA8: =AVERAGE(EA2:EA7) -> 27.083333 | ED8: Average | EE8: =AVERAGE(EE2:EE7) -> 34.26 | EF8: =AVERAGE(EF2:EF7) -> 27.26 | EG8: =AVERAGE(EG2:EG6) -> 30.6 | EH8: =AVERAGE(EH2:EH7) -> 25.58 | EK8: Average | EL8: =AVERAGE(EL2:EL7) -> #DIV/0! | EM8: =AVERAGE(EM2:EM7) -> #DIV/0! | EN8: =AVERAGE(EN2:EN6) -> #DIV/0! | EO8: =AVERAGE(EO2:EO7) -> #DIV/0! | ER8: Average | ES8: =AVERAGE(ES2:ES7) -> 34.76 | ET8: =AVERAGE(ET2:ET7) -> 28 | EU8: =AVERAGE(EU2:EU6) -> 30.975 | EV8: =AVERAGE(EV2:EV7) -> 27.05 | EY8: Average | EZ8: =AVERAGE(EZ2:EZ7) -> 35.04 | FA8: =AVERAGE(FA2:FA7) -> 28.26 | FB8: =AVERAGE(FB2:FB6) -> 31.325 | FC8: =AVERAGE(FC2:FC7) -> 26.8 | FF8: Average | FG8: =AVERAGE(FG2:FG7) -> 28.8 | FH8: =AVERAGE(FH2:FH7) -> 29.2 | FI8: =AVERAGE(FI2:FI6) -> #DIV/0! | FJ8: =AVERAGE(FJ2:FJ7) -> #DIV/0! | FM8: Average | FN8: =AVERAGE(FN2:FN7) -> 32.08 | FO8: =AVERAGE(FO2:FO7) -> 29.075 | FP8: =AVERAGE(FP2:FP6) -> 30.725 | FQ8: =AVERAGE(FQ2:FQ7) -> 25.5
A9: STDEV | B9: =STDEV(B2:B7) -> 1.1933147 | C9: =STDEV(C2:C7) -> 1.8605555 | D9: =STDEV(D2:D7) -> 1.846799 | E9: =STDEV(E2:E7) -> 1.0907184 | H9: STDEV | I9: =STDEV(I2:I7) -> #DIV/0! | J9: =STDEV(J2:J7) -> #DIV/0! | K9: =STDEV(K2:K7) -> #DIV/0! | L9: =STDEV(L2:L7) -> #DIV/0! | O9: STDEV | P9: =STDEV(P2:P7) -> 1.1113055 | Q9: =STDEV(Q2:Q7) -> 1.9623116 | R9: =STDEV(R2:R7) -> 1.6104865 | S9: =STDEV(S2:S7) -> 1.6339115 | V9: STDEV | W9: =STDEV(W2:W7) -> 0.70898989 | X9: =STDEV(X2:X7) -> 2.033388 | Y9: =STDEV(Y2:Y7) -> 1.6428634 | Z9: =STDEV(Z2:Z7) -> 1.3644291 | AC9: STDEV | AD9: =STDEV(AD2:AD7) -> 1.4363147 | AE9: =STDEV(AE2:AE7) -> 2.2141966 | AF9: =STDEV(AF2:AF7) -> 1.7308957 | AG9: =STDEV(AG2:AG7) -> 1.8239152 | AJ9: STDEV | AK9: =STDEV(AK2:AK7) -> 1.1502174 | AL9: =STDEV(AL2:AL7) -> 2.2441034 | AM9: =STDEV(AM2:AM7) -> 1.740881 | AN9: =STDEV(AN2:AN7) -> 1.4761436 | AQ9: STDEV | AR9: =STDEV(AR2:AR7) -> 1.183216 | AS9: =STDEV(AS2:AS7) -> 2.0370731 | AT9: =STDEV(AT2:AT7) -> 1.7758566 | AU9: =STDEV(AU2:AU7) -> 1.3880442 | AX9: STDEV | AY9: =STDEV(AY2:AY7) -> 1.1600287 | AZ9: =STDEV(AZ2:AZ7) -> 2.0432001 | BA9: =STDEV(BA2:BA7) -> 1.7431772 | BB9: =STDEV(BB2:BB7) -> 1.3847984 | BE9: STDEV | BF9: =STDEV(BF2:BF7) -> 1.2237919 | BG9: =STDEV(BG2:BG7) -> 2.1417283 | BH9: =STDEV(BH2:BH7) -> 1.6690317 | BI9: =STDEV(BI2:BI7) -> 1.1570076 | BL9: STDEV | BM9: =STDEV(BM2:BM7) -> 1.5015547 | BN9: =STDEV(BN2:BN7) -> 2.1191193 | BO9: =STDEV(BO2:BO7) -> 1.7224014 | BP9: =STDEV(BP2:BP7) -> 1.3790093 | BS9: STDEV | BT9: =STDEV(BT2:BT7) -> 1.3793718 | BU9: =STDEV(BU2:BU7) -> 2.7169223 | BV9: =STDEV(BV2:BV7) -> 1.6589153 | BW9: =STDEV(BW2:BW7) -> 1.1720353 | BZ9: STDEV | CA9: =STDEV(CA2:CA7) -> 2.1360399 | CB9: =STDEV(CB2:CB7) -> 2.2196096 | CC9: =STDEV(CC2:CC7) -> 1.686021 | CD9: =STDEV(CD2:CD7) -> 0.84616783 | CG9: STDEV | CH9: =STDEV(CH2:CH7) -> 1.6087262 | CI9: =STDEV(CI2:CI7) -> 2.2940503 | CJ9: =STDEV(CJ2:CJ7) -> 2.0366639 | CK9: =STDEV(CK2:CK7) -> 1.068488 | CN9: STDEV | CO9: =STDEV(CO2:CO7) -> 1.8833481 | CP9: =STDEV(CP2:CP7) -> 2.1444502 | CQ9: =STDEV(CQ2:CQ6) -> 0.7733046 | CR9: =STDEV(CR2:CR7) -> 0.81342896 | CU9: STDEV | CV9: =STDEV(CV2:CV7) -> 1.9301986 | CW9: =STDEV(CW2:CW7) -> 2.328662 | CX9: =STDEV(CX2:CX6) -> 0.70569115 | CY9: =STDEV(CY2:CY7) -> 0.90553851 | DB9: STDEV | DC9: =STDEV(DC2:DC7) -> 2.3864199 | DD9: =STDEV(DD2:DD7) -> 2.0264912 | DE9: =STDEV(DE2:DE6) -> 0.73824115 | DF9: =STDEV(DF2:DF7) -> 0.36560452 | DI9: STDEV | DJ9: =STDEV(DJ2:DJ7) -> 2.4337214 | DK9: =STDEV(DK2:DK7) -> 2.0684938 | DL9: =STDEV(DL2:DL6) -> 0.86486993 | DM9: =STDEV(DM2:DM7) -> 0.65319726 | DP9: STDEV | DQ9: =STDEV(DQ2:DQ7) -> 2.585859 | DR9: =STDEV(DR2:DR7) -> 1.947049 | DS9: =STDEV(DS2:DS6) -> 0.80498447 | DT9: =STDEV(DT2:DT7) -> 0.58906706 | DW9: STDEV | DX9: =STDEV(DX2:DX7) -> 2.8223513 | DY9: =STDEV(DY2:DY7) -> 2.2348751 | DZ9: =STDEV(DZ2:DZ6) -> 1.0922454 | EA9: =STDEV(EA2:EA7) -> 0.72502874 | ED9: STDEV | EE9: =STDEV(EE2:EE7) -> 3.4724631 | EF9: =STDEV(EF2:EF7) -> 1.7672012 | EG9: =STDEV(EG2:EG6) -> 0.678233 | EH9: =STDEV(EH2:EH7) -> 1.4411801 | EK9: STDEV | EL9: =STDEV(EL2:EL6) -> #DIV/0! | EM9: =STDEV(EM2:EM7) -> #DIV/0! | EN9: =STDEV(EN2:EN6) -> #DIV/0! | EO9: =STDEV(EO2:EO7) -> #DIV/0! | ER9: STDEV | ES9: =STDEV(ES2:ES6) -> 1.397617 | ET9: =STDEV(ET2:ET7) -> 2.1691012 | EU9: =STDEV(EU2:EU6) -> 0.7804913 | EV9: =STDEV(EV2:EV7) -> 0.97467943 | EY9: STDEV | EZ9: =STDEV(EZ2:EZ6) -> 1.7211914 | FA9: =STDEV(FA2:FA7) -> 1.961632 | FB9: =STDEV(FB2:FB6) -> 1.059481 | FC9: =STDEV(FC2:FC7) -> 1.344123 | FF9: STDEV | FG9: =STDEV(FG2:FG6) -> #DIV/0! | FH9: =STDEV(FH2:FH7) -> #DIV/0! | FI9: =STDEV(FI2:FI6) -> #DIV/0! | FJ9: =STDEV(FJ2:FJ7) -> #DIV/0! | FM9: STDEV | FN9: =STDEV(FN2:FN6) -> 5.382069 | FO9: =STDEV(FO2:FO7) -> 3.2221887 | FP9: =STDEV(FP2:FP6) -> 1.5261608 | FQ9: =STDEV(FQ2:FQ7) -> 2.1656408
A10: SEM | B10: =B9/(SQRT(6)) -> 0.48716869 | C10: =C9/(SQRT(6)) -> 0.75956859 | D10: =D9/(SQRT(6)) -> 0.75395255 | E10: =E9/(SQRT(6)) -> 0.44528393 | H10: SEM | I10: =I9/(SQRT(6)) -> #DIV/0! | J10: =J9/(SQRT(6)) -> #DIV/0! | K10: =K9/(SQRT(6)) -> #DIV/0! | L10: =L9/(SQRT(6)) -> #DIV/0! | O10: SEM | P10: =P9/(SQRT(6)) -> 0.45368859 | Q10: =Q9/(SQRT(6)) -> 0.80111034 | R10: =R9/(SQRT(6)) -> 0.65747835 | S10: =S9/(SQRT(6)) -> 0.66704156 | V10: SEM | W10: =W9/(SQRT(6)) -> 0.28944391 | X10: =X9/(SQRT(6)) -> 0.83012717 | Y10: =Y9/(SQRT(6)) -> 0.67069616 | Z10: =Z9/(SQRT(6)) -> 0.55702583 | AC10: SEM | AD10: =AD9/(SQRT(6)) -> 0.58637303 | AE10: =AE9/(SQRT(6)) -> 0.90394198 | AF10: =AF9/(SQRT(6)) -> 0.70663522 | AG10: =AG9/(SQRT(6)) -> 0.74461026 | AJ10: SEM | AK10: =AK9/(SQRT(6)) -> 0.46957428 | AL10: =AL9/(SQRT(6)) -> 0.91615137 | AM10: =AM9/(SQRT(6)) -> 0.71071169 | AN10: =AN9/(SQRT(6)) -> 0.60263311 | AQ10: SEM | AR10: =AR9/(SQRT(6)) -> 0.48304589 | AS10: =AS9/(SQRT(6)) -> 0.8316316 | AT10: =AT9/(SQRT(6)) -> 0.72499042 | AU10: =AU9/(SQRT(6)) -> 0.56666667 | AX10: SEM | AY10: =AY9/(SQRT(6)) -> 0.47357975 | AZ10: =AZ9/(SQRT(6)) -> 0.83413295 | BA10: =BA9/(SQRT(6)) -> 0.7116491 | BB10: =BB9/(SQRT(6)) -> 0.56534159 | BE10: SEM | BF10: =BF9/(SQRT(6)) -> 0.49961096 | BG10: =BG9/(SQRT(6)) -> 0.87435691 | BH10: =BH9/(SQRT(6)) -> 0.68137932 | BI10: =BI9/(SQRT(6)) -> 0.47234639 | BL10: SEM | BM10: =BM9/(SQRT(6)) -> 0.61300716 | BN10: =BN9/(SQRT(6)) -> 0.86512684 | BO10: =BO9/(SQRT(6)) -> 0.70316744 | BP10: =BP9/(SQRT(6)) -> 0.56297819 | BS10: SEM | BT10: =BT9/(SQRT(6)) -> 0.56312619 | BU10: =BU9/(SQRT(6)) -> 1.1091789 | BV10: =BV9/(SQRT(6)) -> 0.67724934 | BW10: =BW9/(SQRT(6)) -> 0.47848139 | BZ10: SEM | CA10: =CA9/(SQRT(6)) -> 0.87203466 | CB10: =CB9/(SQRT(6)) -> 0.90615181 | CC10: =CC9/(SQRT(6)) -> 0.68831517 | CD10: =CD9/(SQRT(6)) -> 0.34544657 | CG10: SEM | CH10: =CH9/(SQRT(6)) -> 0.65675972 | CI10: =CI9/(SQRT(6)) -> 0.9365421 | CJ10: =CJ9/(SQRT(6)) -> 0.83146457 | CK10: =CK9/(SQRT(6)) -> 0.43620841 | CN10: SEM | CO10: =CO9/(SQRT(6)) -> 0.76887364 | CP10: =CP9/(SQRT(6)) -> 0.87546813 | CQ10: =CQ9/(SQRT(5)) -> 0.34583233 | CR10: =CR9/(SQRT(6)) -> 0.33208098 | CU10: SEM | CV10: =CV9/(SQRT(6)) -> 0.78800028 | CW10: =CW9/(SQRT(6)) -> 0.95067228 | CX10: =CX9/(SQRT(5)) -> 0.31559468 | CY10: =CY9/(SQRT(6)) -> 0.36968455 | DB10: SEM | DC10: =DC9/(SQRT(6)) -> 0.97425185 | DD10: =DD9/(SQRT(6)) -> 0.82731158 | DE10: =DE9/(SQRT(5)) -> 0.33015148 | DF10: =DF9/(SQRT(6)) -> 0.14925742 | DI10: SEM | DJ10: =DJ9/(SQRT(6)) -> 0.99356261 | DK10: =DK9/(SQRT(6)) -> 0.84445906 | DL10: =DL9/(SQRT(5)) -> 0.38678159 | DM10: =DM9/(SQRT(6)) -> 0.26666667 | DP10: SEM | DQ10: =DQ9/(SQRT(6)) -> 1.0556725 | DR10: =DR9/(SQRT(6)) -> 0.79487945 | DS10: =DS9/(SQRT(5)) -> 0.36 | DT10: =DT9/(SQRT(6)) -> 0.24048562 | DW10: SEM | DX10: =DX9/(SQRT(6)) -> 1.1522201 | DY10: =DY9/(SQRT(6)) -> 0.91238393 | DZ10: =DZ9/(SQRT(5)) -> 0.48846699 | EA10: =EA9/(SQRT(6)) -> 0.29599174 | ED10: SEM | EE10: =EE9/(SQRT(5)) -> 1.5529327 | EF10: =EF9/(SQRT(5)) -> 0.79031639 | EG10: =EG9/(SQRT(4)) -> 0.3391165 | EH10: =EH9/(SQRT(5)) -> 0.64451532 | EK10: SEM | EL10: =EL9/(SQRT(5)) -> #DIV/0! | EM10: =EM9/(SQRT(5)) -> #DIV/0! | EN10: =EN9/(SQRT(4)) -> #DIV/0! | EO10: =EO9/(SQRT(5)) -> #DIV/0! | ER10: SEM | ES10: =ES9/(SQRT(5)) -> 0.62503333 | ET10: =ET9/(SQRT(5)) -> 0.97005155 | EU10: =EU9/(SQRT(4)) -> 0.39024565 | EV10: =EV9/(SQRT(4)) -> 0.48733972 | EY10: SEM | EZ10: =EZ9/(SQRT(5)) -> 0.76974022 | FA10: =FA9/(SQRT(5)) -> 0.87726849 | FB10: =FB9/(SQRT(4)) -> 0.5297405 | FC10: =FC9/(SQRT(4)) -> 0.67206151 | FF10: SEM | FG10: =FG9/(SQRT(5)) -> #DIV/0! | FH10: =FH9/(SQRT(4)) -> #DIV/0! | FI10: =FI9/(SQRT(4)) -> #DIV/0! | FJ10: =FJ9/(SQRT(4)) -> #DIV/0! | FM10: SEM | FN10: =FN9/(SQRT(5)) -> 2.4069344 | FO10: =FO9/(SQRT(4)) -> 1.6110943 | FP10: =FP9/(SQRT(4)) -> 0.76308038 | FQ10: =FQ9/(SQRT(3)) -> 1.2503333
A11: 43325 | H11: 43329 | O11: 43332 | V11: 43339 | AC11: 43348 | AJ11: 43355 | AQ11: 43362 | AX11: 43369 | BE11: 43376 | BL11: 43385 | BS11: 43390 | BZ11: 43398 | CG11: 43404 | CN11: 43411 | CU11: 43418 | DB11: 43425 | DI11: 43432 | DP11: 43439 | DW11: 43446 | ED11: 43453 | EK11: 43462 | ER11: 43468 | EY11: 43474 | FF11: 43482 | FM11: 43487
A13: Week | B13: 0 | C13: 1 | D13: 2 | E13: 3 | F13: 4 | G13: 5 | H13: 6 | I13: 7 | J13: 8 | K13: 9 | L13: 10 | M13: 11 | N13: 12 | O13: 13 | P13: 14 | Q13: 15 | R13: 16 | S13: 17 | T13: 18 | U13: 19 | V13: 20 | W13: 21 | X13: 22 | Y13: 23
A14: AT Avg | B14: 25.3 | C14: 23.05 | D14: 24.066667 | E14: 24.95 | F14: 26.15 | G14: 27.3 | H14: 27.183333 | I14: 27.783333 | J14: 28.633333 | K14: 29.166667 | L14: 30.133333 | M14: 30 | N14: 31.05 | O14: 31.216667 | P14: 32.25 | Q14: 32.95 | R14: 33.566667 | S14: 34.383333 | T14: 34.26 | U14: n/a | V14: 34.76 | W14: 35.04 | X14: n/a | Y14: 32.08
A15: AT SEM | B15: 0.48716869 | C15: 0.45368859 | D15: 0.28944391 | E15: 0.58637303 | F15: 0.46957428 | G15: 0.48304589 | H15: 0.47357975 | I15: 0.49961096 | J15: 0.61300716 | K15: 0.56312619 | L15: 0.87203466 | M15: 0.65675972 | N15: 0.76887364 | O15: 0.78800028 | P15: 0.97425185 | Q15: 0.99356261 | R15: 1.0556725 | S15: 1.1522201 | T15: 1.5529327 | V15: 0.62503333 | W15: 0.76974022 | Y15: 2.4069344
A16: AA Avg | B16: 25.083333 | C16: 23.033333 | D16: 23.333333 | E16: 25.166667 | F16: 24.8 | G16: 25.016667 | H16: 25.233333 | I16: 25.65 | J16: 25.633333 | K16: 26.283333 | L16: 26.066667 | M16: 25.866667 | N16: 26.933333 | O16: 27.433333 | P16: 26.466667 | Q16: 27.333333 | R16: 27.45 | S16: 27.833333 | T16: 27.26 | U16: n/a | V16: 28 | W16: 28.26 | X16: n/a | Y16: 29.075
A17: AA SEM | B17: 0.75956859 | C17: 0.80111034 | D17: 0.83012717 | E17: 0.90394198 | F17: 0.91615137 | G17: 0.8316316 | H17: 0.83413295 | I17: 0.87435691 | J17: 0.86512684 | K17: 1.1091789 | L17: 0.90615181 | M17: 0.9365421 | N17: 0.87546813 | O17: 0.95067228 | P17: 0.82731158 | Q17: 0.84445906 | R17: 0.79487945 | S17: 0.91238393 | T17: 0.79031639 | V17: 0.97005155 | W17: 0.87726849 | Y17: 1.6110943
A18: LT Avg | B18: 24.033333 | C18: 22.716667 | D18: 23.75 | E18: 24 | F18: 25.633333 | G18: 26.283333 | H18: 27.066667 | I18: 27.383333 | J18: 27.933333 | K18: 28.5 | L18: 29.066667 | M18: 29.2 | N18: 29.84 | O18: 30.64 | P18: 30.3 | Q18: 30.64 | R18: 30.54 | S18: 31.26 | T18: 30.6 | U18: n/a | V18: 30.975 | W18: 31.325 | X18: n/a | Y18: 30.725
A19: LT SEM | B19: 0.75395255 | C19: 0.65747835 | D19: 0.67069616 | E19: 0.70663522 | F19: 0.71071169 | G19: 0.72499042 | H19: 0.7116491 | I19: 0.68137932 | J19: 0.70316744 | K19: 0.67724934 | L19: 0.68831517 | M19: 0.83146457 | N19: 0.34583233 | O19: 0.31559468 | P19: 0.33015148 | Q19: 0.38678159 | R19: 0.36 | S19: 0.48846699 | T19: 0.3391165 | V19: 0.39024565 | W19: 0.5297405 | Y19: 0.76308038
A20: LA Avg | B20: 23.983333 | C20: 23.316667 | D20: 23.716667 | E20: 24.666667 | F20: 24.45 | G20: 25.466667 | H20: 26.416667 | I20: 26.166667 | J20: 27.216667 | K20: 26.716667 | L20: 26.7 | M20: 27.616667 | N20: 26.183333 | O20: 26.4 | P20: 26.983333 | Q20: 26.733333 | R20: 26.65 | S20: 27.083333 | T20: 25.58 | U20: n/a | V20: 27.05 | W20: 26.8 | X20: n/a | Y20: 25.5
A21: LA SEM | B21: 0.44528393 | C21: 0.66704156 | D21: 0.55702583 | E21: 0.74461026 | F21: 0.60263311 | G21: 0.56666667 | H21: 0.56534159 | I21: 0.47234639 | J21: 0.56297819 | K21: 0.47848139 | L21: 0.34544657 | M21: 0.43620841 | N21: 0.33208098 | O21: 0.36968455 | P21: 0.14925742 | Q21: 0.26666667 | R21: 0.24048562 | S21: 0.29599174 | T21: 0.64451532 | V21: 0.48733972 | W21: 0.67206151 | Y21: 1.2503333
A25: Week | B25: 0 | C25: 1 | D25: 2 | E25: 3 | F25: 4 | G25: 5 | H25: 6 | I25: 7 | J25: 8 | K25: 9 | L25: 10 | M25: 11 | N25: 12 | O25: 13 | P25: 14 | Q25: 15 | R25: 16 | S25: 17 | T25: 18 | U25: 19 | V25: 20 | W25: 21 | X25: 22 | Y25: 23
A26: AT Avg | B26: 25.3 | C26: 23.05 | D26: 24.066667 | E26: 24.95 | F26: 26.15 | G26: 27.3 | H26: 27.183333 | I26: 27.783333 | J26: 28.633333 | K26: 29.166667 | L26: 30.133333 | M26: 30 | N26: 31.05 | O26: 31.216667 | P26: 32.25 | Q26: 32.95 | R26: 33.566667 | S26: 34.383333 | T26: 34.26 | V26: 34.76 | W26: 35.04 | Y26: 32.08
A27: AA Avg | B27: 25.083333 | C27: 23.033333 | D27: 23.333333 | E27: 25.166667 | F27: 24.8 | G27: 25.016667 | H27: 25.233333 | I27: 25.65 | J27: 25.633333 | K27: 26.283333 | L27: 26.066667 | M27: 25.866667 | N27: 26.933333 | O27: 27.433333 | P27: 26.466667 | Q27: 27.333333 | R27: 27.45 | S27: 27.833333 | T27: 27.26 | V27: 28 | W27: 28.26 | Y27: 29.075
A28: LT Avg | B28: 24.033333 | C28: 22.716667 | D28: 23.75 | E28: 24 | F28: 25.633333 | G28: 26.283333 | H28: 27.066667 | I28: 27.383333 | J28: 27.933333 | K28: 28.5 | L28: 29.066667 | M28: 29.2 | N28: 29.84 | O28: 30.64 | P28: 30.3 | Q28: 30.64 | R28: 30.54 | S28: 31.26 | T28: 30.6 | V28: 30.975 | W28: 31.325 | Y28: 30.725
A29: LA Avg | B29: 23.983333 | C29: 23.316667 | D29: 23.716667 | E29: 24.666667 | F29: 24.45 | G29: 25.466667 | H29: 26.416667 | I29: 26.166667 | J29: 27.216667 | K29: 26.716667 | L29: 26.7 | M29: 27.616667 | N29: 26.183333 | O29: 26.4 | P29: 26.983333 | Q29: 26.733333 | R29: 26.65 | S29: 27.083333 | T29: 25.58 | V29: 27.05 | W29: 26.8 | Y29: 25.5

Sheet Food Consumed
A1: Week 1 | B1: AT-pre | C1: AT-post | D1: AT-diff | E1: AA-pre | F1: AA-post | G1: AA-diff | H1: LT-pre | I1: LT-post | J1: LT-diff | K1: LA-pre | L1: LA-post | M1: LA-diff | N1: 8/17/2018-8/20/2018 | Q1: Week | R1: 1 | S1: 2 | T1: 3 | U1: 4 | V1: 5 | W1: 6 | X1: 7 | Y1: 8 | Z1: 9 | AA1: 10 | AB1: 11 | AC1: 12 | AD1: 13 | AE1: 14 | AF1: 15 | AG1: 16 | AH1: 17 | AI1: 18 | AJ1: 19 | AK1: 20 | AL1: 21 | AM1: 22 | AN1: 23 | AQ1: Week | AR1: 1 | AS1: 2 | AT1: 3 | AU1: 8 | AV1: 10 | AW1: 11 | AX1: 12 | AY1: 13 | AZ1: 14 | BA1: 15 | BB1: 16 | BC1: 17 | BD1: 18 | BE1: 19 | BF1: 20 | BG1: 21 | BH1: 23
A2: 1 | B2: 353.6 | C2: 312.9 | D2: =((B2-C2)/4)/3 -> 3.3916667 | E2: 408 | F2: 392.3 | G2: =((E2-F2)/4)/3 -> 1.3083333 | H2: 409.4 | I2: 390.4 | J2: =((H2-I2)/3)/3 -> 2.1111111 | K2: 387 | L2: 371.7 | M2: =((K2-L2)/3)/3 -> 1.7 | N2: 3 days | Q2: AT Avg | R2: 2.7708333 | S2: 2.0107143 | T2: 2.6930556 | U2: 4.8892857 | V2: 2.4875 | W2: 2.4214286 | X2: 2.4303571 | Y2: 2.4236111 | Z2: 2.17 | AA2: 2.49375 | AB2: 2.3375 | AC2: 3.0142857 | AD2: 2.9535714 | AE2: 2.5071429 | AF2: 2.7964286 | AG2: 2.9410714 | AH2: 2.9089286 | AI2: 3.4464286 | AJ2: 3.7546296 | AK2: 2.7819444 | AL2: 2.9194444 | AM2: metabolic cages | AN2: 3.6083333 | AQ2: AT Avg | AR2: 2.7708333 | AS2: 2.0107143 | AT2: 2.6930556 | AU2: 2.4236111 | AV2: 2.49375 | AW2: 2.3375 | AX2: 3.0142857 | AY2: 2.9535714 | AZ2: 2.5071429 | BA2: 2.7964286 | BB2: 2.9410714 | BC2: 2.9089286 | BD2: 3.4464286 | BE2: 3.7546296 | BF2: 2.7819444 | BG2: 2.9194444 | BH2: 3.6083333
A3: 2 | B3: 334.2 | C3: 321.3 | D3: =((B3-C3)/2)/3 -> 2.15 | E3: 388 | F3: 379.9 | G3: =((E3-F3)/2)/3 -> 1.35 | H3: 376.4 | I3: 358.2 | J3: =((H3-I3)/3)/3 -> 2.0222222 | K3: 363.4 | L3: 349.4 | M3: =((K3-L3)/3)/3 -> 1.5555556 | Q3: AT SEM | R3: 0.62083333 | S3: 0.21071429 | T3: 0.18194444 | U3: 3.1107143 | V3: 0.23035714 | W3: 0.15 | X3: 0.076785714 | Y3: 0.0041666667 | Z3: 0.84 | AA3: 0.0875 | AB3: 0.029166667 | AC3: 0.12857143 | AD3: 0.16071429 | AE3: 0.12857143 | AF3: 0.060714286 | AG3: 0.1125 | AH3: 0.041071429 | AI3: 0.40357143 | AJ3: 0.28425926 | AK3: 0.040277778 | AL3: 0.0027777778 | AM3: metabolic cages | AN3: 0.34166667 | AQ3: AT SEM | AR3: 0.62083333 | AS3: 0.21071429 | AT3: 0.18194444 | AU3: 0.0041666667 | AV3: 0.0875 | AW3: 0.029166667 | AX3: 0.12857143 | AY3: 0.16071429 | AZ3: 0.12857143 | BA3: 0.060714286 | BB3: 0.1125 | BC3: 0.041071429 | BD3: 0.40357143 | BE3: 0.28425926 | BF3: 0.040277778 | BG3: 0.0027777778 | BH3: 0.34166667
A4: Avg | D4: =AVERAGE(D2:D3) -> 2.7708333 | G4: =AVERAGE(G2:G3) -> 1.3291667 | J4: =AVERAGE(J2:J3) -> 2.0666667 | M4: =AVERAGE(M2:M3) -> 1.6277778 | Q4: AA Avg | R4: 1.3291667 | S4: 3.4892857 | T4: 2.1791667 | U4: 6.3267857 | V4: 4.8785714 | W4: 6.0392857 | X4: -3.5732143 | Y4: 2.2888889 | Z4: 0.92 | AA4: 2.2328125 | AB4: 2.0861111 | AC4: 2.6214286 | AD4: 3.4714286 | AE4: 2.5928571 | AF4: 2.5095238 | AG4: 3.1952381 | AH4: 2.4261905 | AI4: 3.5 | AJ4: 3.3407407 | AK4: 3.0138889 | AL4: 3.15 | AM4: metabolic cages | AN4: 4.44 | AQ4: AA Avg | AR4: 1.3291667 | AS4: 3.4892857 | AT4: 2.1791667 | AU4: 2.2888889 | AV4: 2.2328125 | AW4: 2.0861111 | AX4: 2.6214286 | AY4: 3.4714286 | AZ4: 2.5928571 | BA4: 2.5095238 | BB4: 3.1952381 | BC4: 2.4261905 | BD4: 3.5 | BE4: 3.3407407 | BF4: 3.0138889 | BG4: 3.15 | BH4: 4.44
A5: Stdev | D5: =STDEV(D2:D3) -> 0.87799092 | G5: =STDEV(G2:G3) -> 0.029462783 | J5: =STDEV(J2:J3) -> 0.062853936 | M5: =STDEV(M2:M3) -> 0.10213765 | Q5: AA SEM | R5: 0.020833333 | S5: 0.91785714 | T5: 0.60972222 | U5: 2.9767857 | V5: 2.4714286 | W5: 10.639286 | X5: 8.7196429 | Y5: 0.055555556 | Z5: 1.95 | AA5: 0.1578125 | AB5: 0.11630234 | AC5: 0.20999676 | AD5: 0.35573532 | AE5: 0.30664411 | AF5: 0.25981853 | AG5: 0.26394229 | AH5: 0.04130798 | AI5: 0.64611608 | AJ5: 0.23518519 | AK5: 0.27639936 | AL5: 0.26943013 | AM5: metabolic cages | AN5: 0.18 | AQ5: AA SEM | AR5: 0.020833333 | AS5: 0.91785714 | AT5: 0.60972222 | AU5: 0.055555556 | AV5: 0.1578125 | AW5: 0.11630234 | AX5: 0.20999676 | AY5: 0.35573532 | AZ5: 0.30664411 | BA5: 0.25981853 | BB5: 0.26394229 | BC5: 0.04130798 | BD5: 0.64611608 | BE5: 0.23518519 | BF5: 0.27639936 | BG5: 0.26943013 | BH5: 0.18
A6: SEM | D6: =D5/(SQRT(2)) -> 0.62083333 | G6: =G5/(SQRT(2)) -> 0.020833333 | J6: =J5/(SQRT(2)) -> 0.044444444 | M6: =M5/(SQRT(2)) -> 0.072222222 | Q6: LT Avg | R6: 2.0666667 | S6: 4.9888889 | T6: 2.2777778 | U6: 2.2714286 | V6: 2.402381 | W6: 2.497619 | X6: 2.6380952 | Y6: 3.0055556 | Z6: 1.21 | AA6: 2.8666667 | AB6: 2.3833333 | AC6: 3.2059524 | AD6: 3.1928571 | AE6: 2.6095238 | AF6: 1.4678571 | AG6: 2.9214286 | AH6: 2.8761905 | AI6: 3.1178571 | AJ6: 3.5111111 | AK6: 2.8125 | AL6: 2.9791667 | AM6: metabolic cages | AN6: 3.89 | AQ6: LT Avg | AR6: 2.0666667 | AS6: 4.9888889 | AT6: 2.2777778 | AU6: 3.0055556 | AV6: 2.8666667 | AW6: 2.3833333 | AX6: 3.2059524 | AY6: 3.1928571 | AZ6: 2.6095238 | BA6: 1.4678571 | BB6: 2.9214286 | BC6: 2.8761905 | BD6: 3.1178571 | BE6: 3.5111111 | BF6: 2.8125 | BG6: 2.9791667 | BH6: 3.89
Q7: LT SEM | R7: 0.044444444 | S7: 0.48888889 | T7: 0.21481481 | U7: 0.052380952 | V7: 0.035714286 | W7: 0.045238095 | X7: 0.028571429 | Y7: 0.0092592593 | Z7: 2.0033333 | AA7: 0.15416667 | AB7: 0.083333333 | AC7: 0.17261905 | AD7: 0.33571429 | AE7: 0.12380952 | AF7: 1.1464286 | AG7: 0.13571429 | AH7: 0.22380952 | AI7: 0.060714286 | AJ7: 0.044444444 | AK7: 0.0875 | AL7: 0.1375 | AM7: metabolic cages | AN7: 0.28 | AQ7: LT SEM | AR7: 0.044444444 | AS7: 0.48888889 | AT7: 0.21481481 | AU7: 0.0092592593 | AV7: 0.15416667 | AW7: 0.083333333 | AX7: 0.17261905 | AY7: 0.33571429 | AZ7: 0.12380952 | BA7: 1.1464286 | BB7: 0.13571429 | BC7: 0.22380952 | BD7: 0.060714286 | BE7: 0.044444444 | BF7: 0.0875 | BG7: 0.1375 | BH7: 0.28
A8: Week 2 | B8: AT-pre | C8: AT-post | D8: AT-diff | E8: AA-pre | F8: AA-post | G8: AA-diff | H8: LT-pre | I8: LT-post | J8: LT-diff | K8: LA-pre | L8: LA-post | M8: LA-diff | N8: 8/20/2018-8/27/2018 | Q8: LA Avg | R8: 1.6277778 | S8: 4.5444444 | T8: 2.937037 | U8: 2.2952381 | V8: 3.0857143 | W8: 3.5190476 | X8: 2.6142857 | Y8: 2.4296296 | Z8: -2.9433333 | AA8: 2.6458333 | AB8: 2.1694444 | AC8: 3.0095238 | AD8: 2.7619048 | AE8: 2.2928571 | AF8: 2.6833333 | AG8: 2.4547619 | AH8: 2.0238095 | AI8: 2.4785714 | AJ8: 2.8481481 | AK8: 2.4583333 | AL8: 2.4111111 | AM8: metabolic cages | AN8: 3.81625 | AQ8: LA Avg | AR8: 1.6277778 | AS8: 4.5444444 | AT8: 2.937037 | AU8: 2.4296296 | AV8: 2.6458333 | AW8: 2.1694444 | AX8: 3.0095238 | AY8: 2.7619048 | AZ8: 2.2928571 | BA8: 2.6833333 | BB8: 2.4547619 | BC8: 2.0238095 | BD8: 2.4785714 | BE8: 2.8481481 | BF8: 2.4583333 | BG8: 2.4111111 | BH8: 3.81625
A9: 1 | B9: 312.9 | C9: 250.7 | D9: =((B9-C9)/4)/7 -> 2.2214286 | E9: 392.3 | F9: 268.9 | G9: =((E9-F9)/4)/7 -> 4.4071429 | H9: 390.4 | I9: 349.9 | J9: =((H9-I9)/3)/3 -> 4.5 | K9: 371.7 | L9: 324.2 | M9: =((K9-L9)/3)/3 -> 5.2777778 | N9: 7 days | Q9: LA SEM | R9: 0.072222222 | S9: 0.73333333 | T9: 0.56296296 | U9: 0.56666667 | V9: 0.94761905 | W9: 1.052381 | X9: 0.41904762 | Y9: 0.22962963 | Z9: 1.5633333 | AA9: 0.21666667 | AB9: 0.15277778 | AC9: 0.2952381 | AD9: 0.22380952 | AE9: 0.04047619 | AF9: 0.62142857 | AG9: 0.045238095 | AH9: 0.019047619 | AI9: 0.19285714 | AJ9: 0.56296296 | AK9: 0.10833333 | AL9: 0.12222222 | AM9: metabolic cages | AN9: 0.49625 | AQ9: LA SEM | AR9: 0.072222222 | AS9: 0.73333333 | AT9: 0.56296296 | AU9: 0.22962963 | AV9: 0.21666667 | AW9: 0.15277778 | AX9: 0.2952381 | AY9: 0.22380952 | AZ9: 0.04047619 | BA9: 0.62142857 | BB9: 0.045238095 | BC9: 0.019047619 | BD9: 0.19285714 | BE9: 0.56296296 | BF9: 0.10833333 | BG9: 0.12222222 | BH9: 0.49625
A10: 2 | B10: 321.3 | C10: 296.1 | D10: =((B10-C10)/2)/7 -> 1.8 | E10: 379.9 | F10: 343.9 | G10: =((E10-F10)/2)/7 -> 2.5714286 | H10: 358.2 | I10: 308.9 | J10: =((H10-I10)/3)/3 -> 5.4777778 | K10: 349.4 | L10: 315.1 | M10: =((K10-L10)/3)/3 -> 3.8111111
A11: Avg | D11: =AVERAGE(D9:D10) -> 2.0107143 | G11: =AVERAGE(G9:G10) -> 3.4892857 | J11: =AVERAGE(J9:J10) -> 4.9888889 | M11: =AVERAGE(M9:M10) -> 4.5444444
A12: Stdev | D12: =STDEV(D9:D10) -> 0.297995 | G12: =STDEV(G9:G10) -> 1.298046 | J12: =STDEV(J9:J10) -> 0.6913933 | M12: =STDEV(M9:M10) -> 1.0370899
A13: SEM | D13: =D12/(SQRT(2)) -> 0.21071429 | G13: =G12/(SQRT(2)) -> 0.91785714 | J13: =J12/(SQRT(2)) -> 0.48888889 | M13: =M12/(SQRT(2)) -> 0.73333333
A15: Week 3 | B15: AT-pre | C15: AT-post | D15: AT-diff | E15: AA-pre | F15: AA-post | G15: AA-diff | H15: LT-pre | I15: LT-post | J15: LT-diff | K15: LA-pre | L15: LA-post | M15: LA-diff | N15: 8/27/2018-9/5/2018
A16: 1 | B16: 562 | C16: 458.5 | D16: =((B16-C16)/4)/9 -> 2.875 | E16: 504.5 | F16: 448 | G16: =((E16-F16)/4)/9 -> 1.5694444 | H16: 515.3 | I16: 448 | J16: =((H16-I16)/3)/9 -> 2.4925926 | K16: 539.8 | L16: 445.3 | M16: =((K16-L16)/3)/9 -> 3.5 | N16: 9 days
A17: 2 | B17: 520.6 | C17: 475.4 | D17: =((B17-C17)/2)/9 -> 2.5111111 | E17: 556.9 | F17: 506.7 | G17: =((E17-F17)/2)/9 -> 2.7888889 | H17: 562.4 | I17: 506.7 | J17: =((H17-I17)/3)/9 -> 2.062963 | K17: 522.8 | L17: 458.7 | M17: =((K17-L17)/3)/9 -> 2.3740741
A18: Avg | D18: =AVERAGE(D16:D17) -> 2.6930556 | G18: =AVERAGE(G16:G17) -> 2.1791667 | J18: =AVERAGE(J16:J17) -> 2.2777778 | M18: =AVERAGE(M16:M17) -> 2.937037
A19: Stdev | D19: =STDEV(D16:D17) -> 0.2573083 | G19: =STDEV(G16:G17) -> 0.86227744 | J19: =STDEV(J16:J17) -> 0.30379402 | M19: =STDEV(M16:M17) -> 0.79614986
A20: SEM | D20: =D19/(SQRT(2)) -> 0.18194444 | G20: =G19/(SQRT(2)) -> 0.60972222 | J20: =J19/(SQRT(2)) -> 0.21481481 | M20: =M19/(SQRT(2)) -> 0.56296296
A22: Week 4 | B22: AT-pre | C22: AT-post | D22: AT-diff | E22: AA-pre | F22: AA-post | G22: AA-diff | H22: LT-pre | I22: LT-post | J22: LT-diff | K22: LA-pre | L22: LA-post | M22: LA-diff | N22: 9/5/2018-9/12/2018
A23: 1 | B23: 458.5 | C23: 234.5 | D23: =((B23-C23)/4)/7 -> 8 | E23: 448 | F23: 187.5 | G23: =((E23-F23)/4)/7 -> 9.3035714 | H23: 448 | I23: 399.2 | J23: =((H23-I23)/3)/7 -> 2.3238095 | K23: 445.3 | L23: 385.2 | M23: =((K23-L23)/3)/7 -> 2.8619048 | N23: 7 days
A24: 2 | B24: 475.4 | C24: 450.5 | D24: =((B24-C24)/2)/7 -> 1.7785714 | E24: 506.7 | F24: 459.8 | G24: =((E24-F24)/2)/7 -> 3.35 | H24: 506.7 | I24: 460.1 | J24: =((H24-I24)/3)/7 -> 2.2190476 | K24: 458.7 | L24: 422.4 | M24: =((K24-L24)/3)/7 -> 1.7285714 | N24: AT and AA post food weights?? (so much consumed, is that realistic?)
A25: Avg | D25: =AVERAGE(D23:D24) -> 4.8892857 | G25: =AVERAGE(G23:G24) -> 6.3267857 | J25: =AVERAGE(J23:J24) -> 2.2714286 | M25: =AVERAGE(M23:M24) -> 2.2952381 | N25: was food dumped out and replaced without a comment? May need to throw out this timepoint
A26: Stdev | D26: =STDEV(D23:D24) -> 4.3992143 | G26: =STDEV(G23:G24) -> 4.2098107 | J26: =STDEV(J23:J24) -> 0.074077853 | M26: =STDEV(M23:M24) -> 0.80138769
A27: SEM | D27: =D26/(SQRT(2)) -> 3.1107143 | G27: =G26/(SQRT(2)) -> 2.9767857 | J27: =J26/(SQRT(2)) -> 0.052380952 | M27: =M26/(SQRT(2)) -> 0.56666667
A29: Week 5 | B29: AT-pre | C29: AT-post | D29: AT-diff | E29: AA-pre | F29: AA-post | G29: AA-diff | H29: LT-pre | I29: LT-post | J29: LT-diff | K29: LA-pre | L29: LA-post | M29: LA-diff | N29: 9/12/2018-9/19/2018
A30: 1 | B30: 484 | C30: 407.9 | D30: =((B30-C30)/4)/7 -> 2.7178571 | E30: 448.7 | F30: 242.9 | G30: =((E30-F30)/4)/7 -> 7.35 | H30: 399.2 | I30: 349.5 | J30: =((H30-I30)/3)/7 -> 2.3666667 | K30: 385.2 | L30: 300.5 | M30: =((K30-L30)/3)/7 -> 4.0333333 | N30: 7 days
A31: 2 | B31: 450.5 | C31: 418.9 | D31: =((B31-C31)/2)/7 -> 2.2571429 | E31: 459.8 | F31: 426.1 | G31: =((E31-F31)/2)/7 -> 2.4071429 | H31: 460.1 | I31: 408.9 | J31: =((H31-I31)/3)/7 -> 2.4380952 | K31: 422.4 | L31: 377.5 | M31: =((K31-L31)/3)/7 -> 2.1380952 | N31: AA post food weights?? (so much consumed, is that realistic?)
A32: Avg | D32: =AVERAGE(D30:D31) -> 2.4875 | G32: =AVERAGE(G30:G31) -> 4.8785714 | J32: =AVERAGE(J30:J31) -> 2.402381 | M32: =AVERAGE(M30:M31) -> 3.0857143 | N32: was food dumped out and replaced without a comment? May need to throw out this timepoint
A33: Stdev | D33: =STDEV(D30:D31) -> 0.3257742 | G33: =STDEV(G30:G31) -> 3.4951278 | J33: =STDEV(J30:J31) -> 0.050507627 | M33: =STDEV(M30:M31) -> 1.3401357
A34: SEM | D34: =D33/(SQRT(2)) -> 0.23035714 | G34: =G33/(SQRT(2)) -> 2.4714286 | J34: =J33/(SQRT(2)) -> 0.035714286 | M34: =M33/(SQRT(2)) -> 0.94761905
A36: Week 6 | B36: AT-pre | C36: AT-post | D36: AT-diff | E36: AA-pre | F36: AA-post | G36: AA-diff | H36: LT-pre | I36: LT-post | J36: LT-diff | K36: LA-pre | L36: LA-post | M36: LA-diff | N36: 9/19/2018-9/26/2018
A37: 1 | B37: 407.9 | C37: 335.9 | D37: =((B37-C37)/4)/7 -> 2.5714286 | E37: 242.9 | F37: 371.7 | G37: =((E37-F37)/4)/7 -> -4.6 | H37: 349.5 | I37: 296.1 | J37: =((H37-I37)/3)/7 -> 2.5428571 | K37: 300.5 | L37: 248.7 | M37: =((K37-L37)/3)/7 -> 2.4666667 | N37: 7 days
A38: 2 | B38: 418.9 | C38: 387.1 | D38: =((B38-C38)/2)/7 -> 2.2714286 | E38: 426.1 | F38: 192.6 | G38: =((E38-F38)/2)/7 -> 16.678571 | H38: 408.9 | I38: 357.4 | J38: =((H38-I38)/3)/7 -> 2.452381 | K38: 377.5 | L38: 281.5 | M38: =((K38-L38)/3)/7 -> 4.5714286 | N38: AA post food weights?? (so much consumed, is that realistic?)
A39: Avg | D39: =AVERAGE(D37:D38) -> 2.4214286 | G39: =AVERAGE(G37:G38) -> 6.0392857 | J39: =AVERAGE(J37:J38) -> 2.497619 | M39: =AVERAGE(M37:M38) -> 3.5190476 | N39: was food dumped out and replaced without a comment? May need to throw out this timepoint
A40: Stdev | D40: =STDEV(D37:D38) -> 0.21213203 | G40: =STDEV(G37:G38) -> 15.046222 | J40: =STDEV(J37:J38) -> 0.063976328 | M40: =STDEV(M37:M38) -> 1.4882914 | N40: have to throw out this timepoint--AA had food added
A41: SEM | D41: =D40/(SQRT(2)) -> 0.15 | G41: =G40/(SQRT(2)) -> 10.639286 | J41: =J40/(SQRT(2)) -> 0.045238095 | M41: =M40/(SQRT(2)) -> 1.052381
A43: Week 7 | B43: AT-pre | C43: AT-post | D43: AT-diff | E43: AA-pre | F43: AA-post | G43: AA-diff | H43: LT-pre | I43: LT-post | J43: LT-diff | K43: LA-pre | L43: LA-post | M43: LA-diff | N43: 9/26/2018-10/3/2018
A44: 1 | B44: 335.9 | C44: 270 | D44: =((B44-C44)/4)/7 -> 2.3535714 | E44: 371.7 | F44: 227.6 | G44: =((E44-F44)/4)/7 -> 5.1464286 | H44: 296.1 | I44: 241.3 | J44: =((H44-I44)/3)/7 -> 2.6095238 | K44: 248.7 | L44: 202.6 | M44: =((K44-L44)/3)/7 -> 2.1952381 | N44: 7 days
A45: 2 | B45: 387.1 | C45: 352 | D45: =((B45-C45)/2)/7 -> 2.5071429 | E45: 192.6 | F45: 364.7 | G45: =((E45-F45)/2)/7 -> -12.292857 | H45: 357.4 | I45: 301.4 | J45: =((H45-I45)/3)/7 -> 2.6666667 | K45: 281.5 | L45: 217.8 | M45: =((K45-L45)/3)/7 -> 3.0333333 | N45: AA post food weights?
...

Sheet g food per mouse per week
A1: Week 1 | B1: AT-pre | C1: AT-post | D1: AT-diff | E1: AA-pre | F1: AA-post | G1: AA-diff | H1: LT-pre | I1: LT-post | J1: LT-diff | K1: LA-pre | L1: LA-post | M1: LA-diff | N1: 8/17/2018-8/20/2018
A2: 1 | B2: 353.6 | C2: 312.9 | D2: =((B2-C2)/4) -> 10.175 | E2: 408 | F2: 392.3 | G2: =((E2-F2)/4) -> 3.925 | H2: 409.4 | I2: 390.4 | J2: =((H2-I2)/3) -> 6.3333333 | K2: 387 | L2: 371.7 | M2: =((K2-L2)/3) -> 5.1 | N2: 3 days
A3: 2 | B3: 334.2 | C3: 321.3 | D3: =((B3-C3)/2) -> 6.45 | E3: 388 | F3: 379.9 | G3: =((E3-F3)/2) -> 4.05 | H3: 376.4 | I3: 358.2 | J3: =((H3-I3)/3) -> 6.0666667 | K3: 363.4 | L3: 349.4 | M3: =((K3-L3)/3) -> 4.6666667
A4: Avg | D4: =AVERAGE(D2:D3) -> 8.3125 | G4: =AVERAGE(G2:G3) -> 3.9875 | J4: =AVERAGE(J2:J3) -> 6.2 | M4: =AVERAGE(M2:M3) -> 4.8833333
A5: Stdev | D5: =STDEV(D2:D3) -> 2.6339728 | G5: =STDEV(G2:G3) -> 0.088388348 | J5: =STDEV(J2:J3) -> 0.18856181 | M5: =STDEV(M2:M3) -> 0.30641294
A6: SEM | D6: =D5/(SQRT(2)) -> 1.8625 | G6: =G5/(SQRT(2)) -> 0.0625 | J6: =J5/(SQRT(2)) -> 0.13333333 | M6: =M5/(SQRT(2)) -> 0.21666667
A8: Week 2 | B8: AT-pre | C8: AT-post | D8: AT-diff | E8: AA-pre | F8: AA-post | G8: AA-diff | H8: LT-pre | I8: LT-post | J8: LT-diff | K8: LA-pre | L8: LA-post | M8: LA-diff | N8: 8/20/2018-8/27/2018
A9: 1 | B9: 312.9 | C9: 250.7 | D9: =((B9-C9)/4) -> 15.55 | E9: 392.3 | F9: 268.9 | G9: =((E9-F9)/4) -> 30.85 | H9: 390.4 | I9: 349.9 | J9: =((H9-I9)/3) -> 13.5 | K9: 371.7 | L9: 324.2 | M9: =((K9-L9)/3) -> 15.833333 | N9: 7 days
A10: 2 | B10: 321.3 | C10: 296.1 | D10: =((B10-C10)/2) -> 12.6 | E10: 379.9 | F10: 343.9 | G10: =((E10-F10)/2) -> 18 | H10: 358.2 | I10: 308.9 | J10: =((H10-I10)/3) -> 16.433333 | K10: 349.4 | L10: 315.1 | M10: =((K10-L10)/3) -> 11.433333
A11: Avg | D11: =AVERAGE(D9:D10) -> 14.075 | G11: =AVERAGE(G9:G10) -> 24.425 | J11: =AVERAGE(J9:J10) -> 14.966667 | M11: =AVERAGE(M9:M10) -> 13.633333
A12: Stdev | D12: =STDEV(D9:D10) -> 2.085965 | G12: =STDEV(G9:G10) -> 9.0863221 | J12: =STDEV(J9:J10) -> 2.0741799 | M12: =STDEV(M9:M10) -> 3.1112698
A13: SEM | D13: =D12/(SQRT(2)) -> 1.475 | G13: =G12/(SQRT(2)) -> 6.425 | J13: =J12/(SQRT(2)) -> 1.4666667 | M13: =M12/(SQRT(2)) -> 2.2
A15: Week 3 | B15: AT-pre | C15: AT-post | D15: AT-diff | E15: AA-pre | F15: AA-post | G15: AA-diff | H15: LT-pre | I15: LT-post | J15: LT-diff | K15: LA-pre | L15: LA-post | M15: LA-diff | N15: 8/27/2018-9/5/2018
A16: 1 | B16: 562 | C16: 458.5 | D16: =((B16-C16)/4) -> 25.875 | E16: 504.5 | F16: 448 | G16: =((E16-F16)/4) -> 14.125 | H16: 515.3 | I16: 448 | J16: =((H16-I16)/3) -> 22.433333 | K16: 539.8 | L16: 445.3 | M16: =((K16-L16)/3) -> 31.5 | N16: 9 days
A17: 2 | B17: 520.6 | C17: 475.4 | D17: =((B17-C17)/2) -> 22.6 | E17: 556.9 | F17: 506.7 | G17: =((E17-F17)/2) -> 25.1 | H17: 562.4 | I17: 506.7 | J17: =((H17-I17)/3) -> 18.566667 | K17: 522.8 | L17: 458.7 | M17: =((K17-L17)/3) -> 21.366667
A18: Avg | D18: =AVERAGE(D16:D17) -> 24.2375 | G18: =AVERAGE(G16:G17) -> 19.6125 | J18: =AVERAGE(J16:J17) -> 20.5 | M18: =AVERAGE(M16:M17) -> 26.433333
A19: Stdev | D19: =STDEV(D16:D17) -> 2.3157747 | G19: =STDEV(G16:G17) -> 7.7604969 | J19: =STDEV(J16:J17) -> 2.7341462 | M19: =STDEV(M16:M17) -> 7.1653487
A20: SEM | D20: =D19/(SQRT(2)) -> 1.6375 | G20: =G19/(SQRT(2)) -> 5.4875 | J20: =J19/(SQRT(2)) -> 1.9333333 | M20: =M19/(SQRT(2)) -> 5.0666667
A22: Week 4 | B22: AT-pre | C22: AT-post | D22: AT-diff | E22: AA-pre | F22: AA-post | G22: AA-diff | H22: LT-pre | I22: LT-post | J22: LT-diff | K22: LA-pre | L22: LA-post | M22: LA-diff | N22: 9/5/2018-9/12/2018
A23: 1 | B23: 458.5 | C23: 234.5 | D23: =((B23-C23)/4) -> 56 | E23: 448 | F23: 187.5 | G23: =((E23-F23)/4) -> 65.125 | H23: 448 | I23: 399.2 | J23: =((H23-I23)/3) -> 16.266667 | K23: 445.3 | L23: 385.2 | M23: =((K23-L23)/3) -> 20.033333 | N23: 7 days
A24: 2 | B24: 475.4 | C24: 450.5 | D24: =((B24-C24)/2) -> 12.45 | E24: 506.7 | F24: 459.8 | G24: =((E24-F24)/2) -> 23.45 | H24: 506.7 | I24: 460.1 | J24: =((H24-I24)/3) -> 15.533333 | K24: 458.7 | L24: 422.4 | M24: =((K24-L24)/3) -> 12.1 | N24: AT and AA post food weights?? (so much consumed, is that realistic?)
A25: Avg | D25: =AVERAGE(D23:D24) -> 34.225 | G25: =AVERAGE(G23:G24) -> 44.2875 | J25: =AVERAGE(J23:J24) -> 15.9 | M25: =AVERAGE(M23:M24) -> 16.066667 | N25: was food dumped out and replaced without a comment? May need to throw out this timepoint
A26: Stdev | D26: =STDEV(D23:D24) -> 30.7945 | G26: =STDEV(G23:G24) -> 29.468675 | J26: =STDEV(J23:J24) -> 0.51854497 | M26: =STDEV(M23:M24) -> 5.6097138
A27: SEM | D27: =D26/(SQRT(2)) -> 21.775 | G27: =G26/(SQRT(2)) -> 20.8375 | J27: =J26/(SQRT(2)) -> 0.36666667 | M27: =M26/(SQRT(2)) -> 3.9666667
A29: Week 5 | B29: AT-pre | C29: AT-post | D29: AT-diff | E29: AA-pre | F29: AA-post | G29: AA-diff | H29: LT-pre | I29: LT-post | J29: LT-diff | K29: LA-pre | L29: LA-post | M29: LA-diff | N29: 9/12/2018-9/19/2018
A30: 1 | B30: 484 | C30: 407.9 | D30: =((B30-C30)/4) -> 19.025 | E30: 448.7 | F30: 242.9 | G30: =((E30-F30)/4) -> 51.45 | H30: 399.2 | I30: 349.5 | J30: =((H30-I30)/3) -> 16.566667 | K30: 385.2 | L30: 300.5 | M30: =((K30-L30)/3) -> 28.233333 | N30: 7 days
A31: 2 | B31: 450.5 | C31: 418.9 | D31: =((B31-C31)/2) -> 15.8 | E31: 459.8 | F31: 426.1 | G31: =((E31-F31)/2) -> 16.85 | H31: 460.1 | I31: 408.9 | J31: =((H31-I31)/3) -> 17.066667 | K31: 422.4 | L31: 377.5 | M31: =((K31-L31)/3) -> 14.966667 | N31: AA post food weights?? (so much consumed, is that realistic?)
A32: Avg | D32: =AVERAGE(D30:D31) -> 17.4125 | G32: =AVERAGE(G30:G31) -> 34.15 | J32: =AVERAGE(J30:J31) -> 16.816667 | M32: =AVERAGE(M30:M31) -> 21.6 | N32: was food dumped out and replaced without a comment? May need to throw out this timepoint
A33: Stdev | D33: =STDEV(D30:D31) -> 2.2804194 | G33: =STDEV(G30:G31) -> 24.465895 | J33: =STDEV(J30:J31) -> 0.35355339 | M33: =STDEV(M30:M31) -> 9.38095
A34: SEM | D34: =D33/(SQRT(2)) -> 1.6125 | G34: =G33/(SQRT(2)) -> 17.3 | J34: =J33/(SQRT(2)) -> 0.25 | M34: =M33/(SQRT(2)) -> 6.6333333
A36: Week 6 | B36: AT-pre | C36: AT-post | D36: AT-diff | E36: AA-pre | F36: AA-post | G36: AA-diff | H36: LT-pre | I36: LT-post | J36: LT-diff | K36: LA-pre | L36: LA-post | M36: LA-diff | N36: 9/19/2018-9/26/2018
A37: 1 | B37: 407.9 | C37: 335.9 | D37: =((B37-C37)/4) -> 18 | E37: 242.9 | F37: 371.7 | G37: =((E37-F37)/4) -> -32.2 | H37: 349.5 | I37: 296.1 | J37: =((H37-I37)/3) -> 17.8 | K37: 300.5 | L37: 248.7 | M37: =((K37-L37)/3) -> 17.266667 | N37: 7 days
A38: 2 | B38: 418.9 | C38: 387.1 | D38: =((B38-C38)/2) -> 15.9 | E38: 426.1 | F38: 192.6 | G38: =((E38-F38)/2) -> 116.75 | H38: 408.9 | I38: 357.4 | J38: =((H38-I38)/3) -> 17.166667 | K38: 377.5 | L38: 281.5 | M38: =((K38-L38)/3) -> 32 | N38: AA post food weights?? (so much consumed, is that realistic?)
A39: Avg | D39: =AVERAGE(D37:D38) -> 16.95 | G39: =AVERAGE(G37:G38) -> 42.275 | J39: =AVERAGE(J37:J38) -> 17.483333 | M39: =AVERAGE(M37:M38) -> 24.633333 | N39: was food dumped out and replaced without a comment? May need to throw out this timepoint
A40: Stdev | D40: =STDEV(D37:D38) -> 1.4849242 | G40: =STDEV(G37:G38) -> 105.32356 | J40: =STDEV(J37:J38) -> 0.44783429 | M40: =STDEV(M37:M38) -> 10.41804 | N40: have to throw out this timepoint--AA had food added
A41: SEM | D41: =D40/(SQRT(2)) -> 1.05 | G41: =G40/(SQRT(2)) -> 74.475 | J41: =J40/(SQRT(2)) -> 0.31666667 | M41: =M40/(SQRT(2)) -> 7.3666667
A43: Week 7 | B43: AT-pre | C43: AT-post | D43: AT-diff | E43: AA-pre | F43: AA-post | G43: AA-diff | H43: LT-pre | I43: LT-post | J43: LT-diff | K43: LA-pre | L43: LA-post | M43: LA-diff | N43: 9/26/2018-10/3/2018
A44: 1 | B44: 335.9 | C44: 270 | D44: =((B44-C44)/4) -> 16.475 | E44: 371.7 | F44: 227.6 | G44: =((E44-F44)/4) -> 36.025 | H44: 296.1 | I44: 241.3 | J44: =((H44-I44)/3) -> 18.266667 | K44: 248.7 | L44: 202.6 | M44: =((K44-L44)/3) -> 15.366667 | N44: 7 days
A45: 2 | B45: 387.1 | C45: 352 | D45: =((B45-C45)/2) -> 17.55 | E45: 192.6 | F45: 364.7 | G45: =((E45-F45)/2) -> -86.05 | H45: 357.4 | I45: 301.4 | J45: =((H45-I45)/3) -> 18.666667 | K45: 281.5 | L45: 217.8 | M45: =((K45-L45)/3) -> 21.233333 | N45: AA post food weights?
A46: Avg | D46: =AVERAGE(D44:D45) -> 17.0125 | G46: =AVERAGE(G44:G45) -> -25.0125 | J46: =AVERAGE(J44:J45) -> 18.466667 | M46: =AVERAGE(M44:M45) -> 18.3 | N46: have to throw out this timepoint--AA had food added
...

Sheet cum food intake take 
A1: g food total | B1: Week | C1: AT_1 | D1: AT_2 | E1: AA_1 | F1: AA_2 | G1: AA_3 | H1: LT_1 | I1: LT_2 | J1: LA_1 | K1: LA_2 | M1: kcal food total | N1: Week | O1: AT_1 | P1: AT_2 | Q1: AA_1 | R1: AA_2 | S1: AA_3 | T1: LT_1 | U1: LT_2 | V1: LA_1 | W1: LA_2 | Y1: kcal/week | Z1: Week | AA1: AT_1 | AB1: AT_2 | AC1: AA_1 | AD1: AA_2 | AE1: AA_3 | AF1: LT_1 | AG1: LT_2 | AH1: LA_1 | AI1: LA_2 | AK1: kcal/week/mouse for each condition total | AL1: Week | AM1: AT | AN1: AA | AO1: LT | AP1: LA | AR1: cumulative kcal/mouse/week | AS1: Week | AT1: AT | AU1: AA | AV1: LT | AW1: LA | AY1: SEM | AZ1: Week | BA1: AT | BB1: AA | BC1: LT | BD1: LA
B2: 1 | C2: =B27-C27 -> 40.7 | D2: =B28-C28 -> 12.9 | E2: =E27-F27 -> 15.7 | F2: =E28-F28 -> 8.1 | H2: =H27-I27 -> 19 | I2: =H28-I28 -> 18.2 | J2: =K27-L27 -> 15.3 | K2: =K28-L28 -> 14 | N2: 1 | O2: =C2*4.53 -> 184.371 | P2: =D2*4.53 -> 58.437 | Q2: =E2*4.53 -> 71.121 | R2: =F2*4.53 -> 36.693 | S2: =G2*4.53 -> 0 | T2: =H2*4.53 -> 86.07 | U2: =I2*4.53 -> 82.446 | V2: =J2*4.53 -> 69.309 | W2: =K2*4.53 -> 63.42 | Z2: 1 | AA2: 184.371 | AB2: 58.437 | AC2: 71.121 | AD2: 36.693 | AE2: 0 | AF2: 86.07 | AG2: 82.446 | AH2: 69.309 | AI2: 63.42 | AL2: 1 | AM2: =SUM(AA2:AB2)/6 -> 40.468 | AN2: =SUM(AC2:AE2)/6 -> 17.969 | AO2: =SUM(AF2:AG2)/6 -> 28.086 | AP2: =SUM(AH2:AI2)/6 -> 22.1215 | AS2: 1 | AT2: =AM2 -> 40.468 | AU2: =AN2 -> 17.969 | AV2: =AO2 -> 28.086 | AW2: =AP2 -> 22.1215 | AZ2: 1 | BA2: =STDEV(AA22:AB22)/SQRT(COUNT(AA22:AB22)) -> 8.437125 | BB2: ????
B3: 2 | C3: =B34-C34 -> 62.2 | D3: =B35-C35 -> 25.2 | E3: =E34-F34 -> 123.4 | F3: =E35-F35 -> 36 | H3: =H34-I34 -> 40.5 | I3: =H35-I35 -> 49.3 | J3: =K34-L34 -> 47.5 | K3: =K35-L35 -> 34.3 | N3: 2 | O3: =C3*4.53 -> 281.766 | P3: =D3*4.53 -> 114.156 | Q3: =E3*4.53 -> 559.002 | R3: =F3*4.53 -> 163.08 | S3: =G3*4.53 -> 0 | T3: =H3*4.53 -> 183.465 | U3: =I3*4.53 -> 223.329 | V3: =J3*4.53 -> 215.175 | W3: =K3*4.53 -> 155.379 | Z3: 2 | AA3: 281.766 | AB3: 114.156 | AC3: 559.002 | AD3: 163.08 | AE3: 0 | AF3: 183.465 | AG3: 223.329 | AH3: 215.175 | AI3: 155.379 | AL3: 2 | AM3: =SUM(AA3:AB3)/6 -> 65.987 | AN3: =SUM(AC3:AE3)/6 -> 120.347 | AO3: =SUM(AF3:AG3)/6 -> 67.799 | AP3: =SUM(AH3:AI3)/6 -> 61.759 | AS3: 2 | AT3: =SUM(AM2:AM3) -> 106.455 | AU3: =SUM(AN2:AN3) -> 138.316 | AV3: =SUM(AO2:AO3) -> 95.885 | AW3: =SUM(AP2:AP3) -> 83.8805 | AZ3: 2 | BA3: =STDEV(AA23:AB23)/SQRT(COUNT(AA23:AB23)) -> 6.68175
B4: 3 | C4: =B41-C41 -> 103.5 | D4: =B42-C42 -> 45.2 | E4: =E41-F41 -> 56.5 | F4: =E42-F42 -> 50.2 | H4: =H41-I41 -> 67.3 | I4: =H42-I42 -> 55.7 | J4: =K48-L48 -> 60.1 | K4: =K42-L42 -> 64.1 | N4: 3 | O4: =C4*4.53 -> 468.855 | P4: =D4*4.53 -> 204.756 | Q4: =E4*4.53 -> 255.945 | R4: =F4*4.53 -> 227.406 | S4: =G4*4.53 -> 0 | T4: =H4*4.53 -> 304.869 | U4: =I4*4.53 -> 252.321 | V4: =J4*4.53 -> 272.253 | W4: =K4*4.53 -> 290.373 | Z4: 3 | AA4: 468.855 | AB4: 204.756 | AC4: 255.945 | AD4: 227.406 | AE4: 0 | AF4: 304.869 | AG4: 252.321 | AH4: 272.253 | AI4: 290.373 | AL4: 3 | AM4: =SUM(AA4:AB4)/6 -> 112.2685 | AN4: =SUM(AC4:AE4)/6 -> 80.5585 | AO4: =SUM(AF4:AG4)/6 -> 92.865 | AP4: =SUM(AH4:AI4)/6 -> 93.771 | AS4: 3 | AT4: =SUM(AM2:AM4) -> 218.7235 | AU4: =SUM(AN2:AN4) -> 218.8745 | AV4: =SUM(AO2:AO4) -> 188.75 | AW4: =SUM(AP2:AP4) -> 177.6515 | AZ4: 3 | BA4: =STDEV(AA24:AB24)/SQRT(COUNT(AA24:AB24)) -> 7.417875
B5: 4 | C5: =B48-C48 -> 224 | D5: =B49-C49 -> 24.9 | E5: =E48-F48 -> 260.5 | F5: =E49-F49 -> 46.9 | H5: =H48-I48 -> 48.8 | I5: =H49-I49 -> 46.6 | J5: =K48-L48 -> 60.1 | K5: =K49-L49 -> 36.3 | N5: 4 | O5: =C5*4.53 -> 1014.72 | P5: =D5*4.53 -> 112.797 | Q5: =E5*4.53 -> 1180.065 | R5: =F5*4.53 -> 212.457 | S5: =G5*4.53 -> 0 | T5: =H5*4.53 -> 221.064 | U5: =I5*4.53 -> 211.098 | V5: =J5*4.53 -> 272.253 | W5: =K5*4.53 -> 164.439 | Z5: 4 | AA5: 1014.72 | AB5: 112.797 | AC5: 1180.065 | AD5: 212.457 | AE5: 0 | AF5: 221.064 | AG5: 211.098 | AH5: 272.253 | AI5: 164.439 | AL5: 4 | AM5: =SUM(AA5:AB5)/6 -> 187.9195 | AN5: =SUM(AC5:AE5)/6 -> 232.087 | AO5: =SUM(AF5:AG5)/6 -> 72.027 | AP5: =SUM(AH5:AI5)/6 -> 72.782 | AS5: 4 | AT5: =SUM(AM2:AM5) -> 406.643 | AU5: =SUM(AN2:AN5) -> 450.9615 | AV5: =SUM(AO2:AO5) -> 260.777 | AW5: =SUM(AP2:AP5) -> 250.4335 | AZ5: 4 | BA5: =STDEV(AA25:AB25)/SQRT(COUNT(AA25:AB25)) -> 98.64075
B6: 5 | C6: =B55-C55 -> 76.1 | D6: =B56-C56 -> 31.6 | E6: =E55-F55 -> 205.8 | F6: =E56-F56 -> 33.7 | H6: =H55-I55 -> 49.7 | I6: =H56-I56 -> 51.2 | J6: =K55-L55 -> 84.7 | K6: =K56-L56 -> 44.9 | N6: 5 | O6: =C6*4.53 -> 344.733 | P6: =D6*4.53 -> 143.148 | Q6: =E6*4.53 -> 932.274 | R6: =F6*4.53 -> 152.661 | S6: =G6*4.53 -> 0 | T6: =H6*4.53 -> 225.141 | U6: =I6*4.53 -> 231.936 | V6: =J6*4.53 -> 383.691 | W6: =K6*4.53 -> 203.397 | Z6: 5 | AA6: 344.733 | AB6: 143.148 | AC6: 932.274 | AD6: 152.661 | AE6: 0 | AF6: 225.141 | AG6: 231.936 | AH6: 383.691 | AI6: 203.397 | AL6: 5 | AM6: =SUM(AA6:AB6)/6 -> 81.3135 | AN6: =SUM(AC6:AE6)/6 -> 180.8225 | AO6: =SUM(AF6:AG6)/6 -> 76.1795 | AP6: =SUM(AH6:AI6)/6 -> 97.848 | AS6: 5 | AT6: =SUM(AM2:AM6) -> 487.9565 | AU6: =SUM(AN2:AN6) -> 631.784 | AV6: =SUM(AO2:AO6) -> 336.9565 | AW6: =SUM(AP2:AP6) -> 348.2815 | AZ6: 5 | BA6: =STDEV(AA26:AB26)/SQRT(COUNT(AA26:AB26)) -> 7.304625
